Workbook

Sheet ⚙ Parámetros
A1: mesoestetic® · Project Scoring System — Parámetros del Modelo
A2: Celdas en azul = inputs editables · Celdas en negro = fórmulas calculadas · Cambia cualquier valor y todo se recalcula
A3: 1. Pesos de Dimensiones (deben sumar 100%)
A4: Dimensión | D4: Peso (%) | E4: Descripción
A5: D1 — Compliance / Legal / Riesgo | B5: 30 | C5: Peso en % (editable)
A6: D2 — Estratégico / Prioridad Consejo | B6: 20 | C6: Peso en % (editable)
A7: D3 — ROI / Valor de negocio | B7: 20 | C7: Peso en % (editable)
A8: D4 — Técnica / Madurez TRL | B8: 12 | C8: Peso en % (editable)
A9: D5 — Implantación / Facilidad | B9: 10 | C9: Peso en % (editable)
A10: D6 — Personas / ESG | B10: 8 | C10: Peso en % (editable)
A11: TOTAL (debe ser 100%) | B11: =SUM(B5:B10) -> 100 | C11: =IF(B11=100,"✓ Correcto","✗ Revisar") -> ✓ Correcto
A13: 2. Parámetros Sigmoid Boost Boost(S) = max( α₀/(1+2^(−β₀·(S−C₀))), α/(1+2^(−β·(S−C))), 1 )
A14: Dim | B14: C₀ (base) | C14: β₀ (base) | D14: α₀ (base) | E14: C (boost) | F14: β (boost) | G14: α (boost) | H14: Peso critr.
A15: D1 — Compliance / Legal / Riesgo | B15: 3 | C15: 1 | D15: 2 | E15: 7 | F15: 2 | G15: 9
A16: D2 — Estratégico / Prioridad Consejo | B16: 4 | C16: 1 | D16: 3 | E16: 8 | F16: 2 | G16: 9
A17: D3 — ROI / Valor de negocio | B17: 4 | C17: 1 | D17: 3 | E17: 8 | F17: 2 | G17: 8
A18: D4 — Técnica / Madurez TRL | B18: 4 | C18: 1 | D18: 3 | E18: 8 | F18: 1.5 | G18: 7
A19: D5 — Implantación / Facilidad | B19: 4 | C19: 1 | D19: 3 | E19: 8 | F19: 1.5 | G19: 7
A20: D6 — Personas / ESG | B20: 4 | C20: 1 | D20: 2 | E20: 8 | F20: 1 | G20: 6
A22: 3. Umbrales de Clasificación de Score
A23: Prioritario Estratégico ≥ | B23: 8.5
A24: Alta Prioridad ≥ | B24: 7
A25: Prioridad Media ≥ | B25: 5.5
A26: Baja Prioridad ≥ | B26: 4
A28: 4. Umbrales de Pools por Horas
A29: Corto — máximo horas | B29: 30
A30: Medio — máximo horas | B30: 100
A32: 5. Aging Factor Score_final = min(Score_base × Aging, 10) Aging = min(1 + (días/365) × tasa, máximo)
A33: Tasa de aging anual | B33: 0.15
A34: Aging máximo | B34: 1.25

Sheet 📋 Evaluación
A1: mesoestetic® · Evaluación de Proyecto Individual
A2: Introduce las notas (1–10) en azul · Todo se calcula automáticamente desde ⚙ Parámetros
A3: Datos del Proyecto
B4: Nombre del proyecto
B5: Área promotora
B6: Tipo de proyecto | C6: p.ej. Integración, Digitalización, BI...
B7: Sponsor ejecutivo | C7: Nombre del sponsor
B8: Fecha de solicitud | C8: dd/mm/aaaa
B9: Días en cartera | C9: =IF(C7="","—",IF(ISNUMBER(C7),TEXT(TODAY()-C7,"0")&" días","—")) -> —
B10: Aging factor | C10: =IF(C7="","×1.000",IF(ISNUMBER(C7),TEXT(MIN(1+MAX(0,TODAY()-C7)/365*'⚙ Parámetros'!B33,'⚙ Parámetros'!B34),"0.000")&"×","×1.000")) -> ×1.000
A12: Evaluación por Dimensiones (notas 1–10 en azul → score se calcula automáticamente)
B13: Criterio de evaluación | C13: Nota (1–10) | D13: Boost (auto) | E13: pw×B×N (auto) | F13: pw×B (auto) | G13: % peso dim | H13: Score dimensión | I13: Clasif.
A14: D1 | B14: Riesgo legal / regulatorio | C14: 5 | D14: =MAX('⚙ Parámetros'!D15/(1+2^(-'⚙ Parámetros'!C15*(C14-'⚙ Parámetros'!B15))),'⚙ Parámetros'!G15/(1+2^(-'⚙ Parámetros'!F15*(C14-'⚙ Parámetros'!E15))),1) -> 1.6 | E14: =30/100*D14*C14 -> 2.4 | F14: =30/100*D14 -> 0.48 | G14: 30%
B15: Seguridad y PRL | C15: 5 | D15: =MAX('⚙ Parámetros'!D15/(1+2^(-'⚙ Parámetros'!C15*(C15-'⚙ Parámetros'!B15))),'⚙ Parámetros'!G15/(1+2^(-'⚙ Parámetros'!F15*(C15-'⚙ Parámetros'!E15))),1) -> 1.6 | E15: =30/100*D15*C15 -> 2.4 | F15: =30/100*D15 -> 0.48 | G15: 30% | H15: =IFERROR(SUM(E14:E17)/SUM(F14:F17),0) -> 5
B16: Riesgo reputacional | C16: 5 | D16: =MAX('⚙ Parámetros'!D15/(1+2^(-'⚙ Parámetros'!C15*(C16-'⚙ Parámetros'!B15))),'⚙ Parámetros'!G15/(1+2^(-'⚙ Parámetros'!F15*(C16-'⚙ Parámetros'!E15))),1) -> 1.6 | E16: =20/100*D16*C16 -> 1.6 | F16: =20/100*D16 -> 0.32 | G16: 20%
B17: Obligación normativa | C17: 5 | D17: =MAX('⚙ Parámetros'!D15/(1+2^(-'⚙ Parámetros'!C15*(C17-'⚙ Parámetros'!B15))),'⚙ Parámetros'!G15/(1+2^(-'⚙ Parámetros'!F15*(C17-'⚙ Parámetros'!E15))),1) -> 1.6 | E17: =20/100*D17*C17 -> 1.6 | F17: =20/100*D17 -> 0.32 | G17: 20%
A18: D2 | B18: Mandato del Consejo | C18: 5 | D18: =MAX('⚙ Parámetros'!D16/(1+2^(-'⚙ Parámetros'!C16*(C18-'⚙ Parámetros'!B16))),'⚙ Parámetros'!G16/(1+2^(-'⚙ Parámetros'!F16*(C18-'⚙ Parámetros'!E16))),1) -> 2 | E18: =35/100*D18*C18 -> 3.5 | F18: =35/100*D18 -> 0.7 | G18: 35%
B19: Expansión internacional | C19: 5 | D19: =MAX('⚙ Parámetros'!D16/(1+2^(-'⚙ Parámetros'!C16*(C19-'⚙ Parámetros'!B16))),'⚙ Parámetros'!G16/(1+2^(-'⚙ Parámetros'!F16*(C19-'⚙ Parámetros'!E16))),1) -> 2 | E19: =25/100*D19*C19 -> 2.5 | F19: =25/100*D19 -> 0.5 | G19: 25% | H19: =IFERROR(SUM(E18:E21)/SUM(F18:F21),0) -> 5
B20: Innovación / I+D | C20: 5 | D20: =MAX('⚙ Parámetros'!D16/(1+2^(-'⚙ Parámetros'!C16*(C20-'⚙ Parámetros'!B16))),'⚙ Parámetros'!G16/(1+2^(-'⚙ Parámetros'!F16*(C20-'⚙ Parámetros'!E16))),1) -> 2 | E20: =20/100*D20*C20 -> 2 | F20: =20/100*D20 -> 0.4 | G20: 20%
B21: Urgencia estratégica | C21: 5 | D21: =MAX('⚙ Parámetros'!D16/(1+2^(-'⚙ Parámetros'!C16*(C21-'⚙ Parámetros'!B16))),'⚙ Parámetros'!G16/(1+2^(-'⚙ Parámetros'!F16*(C21-'⚙ Parámetros'!E16))),1) -> 2 | E21: =20/100*D21*C21 -> 2 | F21: =20/100*D21 -> 0.4 | G21: 20%
A22: D3 | B22: Impacto en ingresos | C22: 5 | D22: =MAX('⚙ Parámetros'!D17/(1+2^(-'⚙ Parámetros'!C17*(C22-'⚙ Parámetros'!B17))),'⚙ Parámetros'!G17/(1+2^(-'⚙ Parámetros'!F17*(C22-'⚙ Parámetros'!E17))),1) -> 2 | E22: =30/100*D22*C22 -> 3 | F22: =30/100*D22 -> 0.6 | G22: 30%
B23: Ahorro de costes | C23: 5 | D23: =MAX('⚙ Parámetros'!D17/(1+2^(-'⚙ Parámetros'!C17*(C23-'⚙ Parámetros'!B17))),'⚙ Parámetros'!G17/(1+2^(-'⚙ Parámetros'!F17*(C23-'⚙ Parámetros'!E17))),1) -> 2 | E23: =25/100*D23*C23 -> 2.5 | F23: =25/100*D23 -> 0.5 | G23: 25% | H23: =IFERROR(SUM(E22:E25)/SUM(F22:F25),0) -> 5
B24: ROI y payback | C24: 5 | D24: =MAX('⚙ Parámetros'!D17/(1+2^(-'⚙ Parámetros'!C17*(C24-'⚙ Parámetros'!B17))),'⚙ Parámetros'!G17/(1+2^(-'⚙ Parámetros'!F17*(C24-'⚙ Parámetros'!E17))),1) -> 2 | E24: =25/100*D24*C24 -> 2.5 | F24: =25/100*D24 -> 0.5 | G24: 25%
B25: Calidad y servicio | C25: 5 | D25: =MAX('⚙ Parámetros'!D17/(1+2^(-'⚙ Parámetros'!C17*(C25-'⚙ Parámetros'!B17))),'⚙ Parámetros'!G17/(1+2^(-'⚙ Parámetros'!F17*(C25-'⚙ Parámetros'!E17))),1) -> 2 | E25: =20/100*D25*C25 -> 2 | F25: =20/100*D25 -> 0.4 | G25: 20%
A26: D4 | B26: Madurez tecnológica (TRL) | C26: 5 | D26: =MAX('⚙ Parámetros'!D18/(1+2^(-'⚙ Parámetros'!C18*(C26-'⚙ Parámetros'!B18))),'⚙ Parámetros'!G18/(1+2^(-'⚙ Parámetros'!F18*(C26-'⚙ Parámetros'!E18))),1) -> 2 | E26: =30/100*D26*C26 -> 3 | F26: =30/100*D26 -> 0.6 | G26: 30%
B27: Integración con ERP/sistemas | C27: 5 | D27: =MAX('⚙ Parámetros'!D18/(1+2^(-'⚙ Parámetros'!C18*(C27-'⚙ Parámetros'!B18))),'⚙ Parámetros'!G18/(1+2^(-'⚙ Parámetros'!F18*(C27-'⚙ Parámetros'!E18))),1) -> 2 | E27: =30/100*D27*C27 -> 3 | F27: =30/100*D27 -> 0.6 | G27: 30% | H27: =IFERROR(SUM(E26:E29)/SUM(F26:F29),0) -> 5
B28: Escalabilidad | C28: 5 | D28: =MAX('⚙ Parámetros'!D18/(1+2^(-'⚙ Parámetros'!C18*(C28-'⚙ Parámetros'!B18))),'⚙ Parámetros'!G18/(1+2^(-'⚙ Parámetros'!F18*(C28-'⚙ Parámetros'!E18))),1) -> 2 | E28: =20/100*D28*C28 -> 2 | F28: =20/100*D28 -> 0.4 | G28: 20%
B29: Ciberseguridad / GDPR | C29: 5 | D29: =MAX('⚙ Parámetros'!D18/(1+2^(-'⚙ Parámetros'!C18*(C29-'⚙ Parámetros'!B18))),'⚙ Parámetros'!G18/(1+2^(-'⚙ Parámetros'!F18*(C29-'⚙ Parámetros'!E18))),1) -> 2 | E29: =20/100*D29*C29 -> 2 | F29: =20/100*D29 -> 0.4 | G29: 20%
A30: D5 | B30: Capacidad interna IT | C30: 5 | D30: =MAX('⚙ Parámetros'!D19/(1+2^(-'⚙ Parámetros'!C19*(C30-'⚙ Parámetros'!B19))),'⚙ Parámetros'!G19/(1+2^(-'⚙ Parámetros'!F19*(C30-'⚙ Parámetros'!E19))),1) -> 2 | E30: =30/100*D30*C30 -> 3 | F30: =30/100*D30 -> 0.6 | G30: 30%
B31: Gestión del cambio | C31: 5 | D31: =MAX('⚙ Parámetros'!D19/(1+2^(-'⚙ Parámetros'!C19*(C31-'⚙ Parámetros'!B19))),'⚙ Parámetros'!G19/(1+2^(-'⚙ Parámetros'!F19*(C31-'⚙ Parámetros'!E19))),1) -> 2 | E31: =35/100*D31*C31 -> 3.5 | F31: =35/100*D31 -> 0.7 | G31: 35% | H31: =IFERROR(SUM(E30:E32)/SUM(F30:F32),0) -> 5
B32: Time-to-value | C32: 5 | D32: =MAX('⚙ Parámetros'!D19/(1+2^(-'⚙ Parámetros'!C19*(C32-'⚙ Parámetros'!B19))),'⚙ Parámetros'!G19/(1+2^(-'⚙ Parámetros'!F19*(C32-'⚙ Parámetros'!E19))),1) -> 2 | E32: =35/100*D32*C32 -> 3.5 | F32: =35/100*D32 -> 0.7 | G32: 35%
A33: D6 | B33: Experiencia del empleado | C33: 5 | D33: =MAX('⚙ Parámetros'!D20/(1+2^(-'⚙ Parámetros'!C20*(C33-'⚙ Parámetros'!B20))),'⚙ Parámetros'!G20/(1+2^(-'⚙ Parámetros'!F20*(C33-'⚙ Parámetros'!E20))),1) -> 1.3333333 | E33: =35/100*D33*C33 -> 2.3333333 | F33: =35/100*D33 -> 0.46666667 | G33: 35%
B34: Sostenibilidad / ESG | C34: 5 | D34: =MAX('⚙ Parámetros'!D20/(1+2^(-'⚙ Parámetros'!C20*(C34-'⚙ Parámetros'!B20))),'⚙ Parámetros'!G20/(1+2^(-'⚙ Parámetros'!F20*(C34-'⚙ Parámetros'!E20))),1) -> 1.3333333 | E34: =35/100*D34*C34 -> 2.3333333 | F34: =35/100*D34 -> 0.46666667 | G34: 35% | H34: =IFERROR(SUM(E33:E35)/SUM(F33:F35),0) -> 5
B35: Formación y cultura | C35: 5 | D35: =MAX('⚙ Parámetros'!D20/(1+2^(-'⚙ Parámetros'!C20*(C35-'⚙ Parámetros'!B20))),'⚙ Parámetros'!G20/(1+2^(-'⚙ Parámetros'!F20*(C35-'⚙ Parámetros'!E20))),1) -> 1.3333333 | E35: =30/100*D35*C35 -> 2 | F35: =30/100*D35 -> 0.4 | G35: 30%
A37: Resultado Final
B38: Score base (sin aging) | C38: =('⚙ Parámetros'!B5/100*H15+'⚙ Parámetros'!B6/100*H19+'⚙ Parámetros'!B7/100*H23+'⚙ Parámetros'!B8/100*H27+'⚙ Parámetros'!B9/100*H31+'⚙ Parámetros'!B10/100*H34) -> 5
B39: Aging factor | C39: =IFERROR(MIN(1+IF(C7<>"",MAX(0,TODAY()-DATEVALUE(C7))/365,0)*'⚙ Parámetros'!B33,'⚙ Parámetros'!B34),1) -> 1
B40: SCORE FINAL | C40: =IFERROR(MIN((('⚙ Parámetros'!B5/100*H15+'⚙ Parámetros'!B6/100*H19+'⚙ Parámetros'!B7/100*H23+'⚙ Parámetros'!B8/100*H27+'⚙ Parámetros'!B9/100*H31+'⚙ Parámetros'!B10/100*H34))*MIN(1+IF(C7<>"",MAX(0,TODAY()-DATEVALUE(C7))/365,0)*'⚙ Parámetros'!B33,'⚙ Parámetros'!B34),10),0) -> 0
B41: Clasificación | C41: =IFERROR(IF(C4<>"",IF(HH15>='⚙ Parámetros'!B23,"⚑ AUTO-PRIORITARIO (D1≥8)",IF(C40>='⚙ Parámetros'!B23,"PRIORITARIO ESTRATÉGICO",IF(C40>='⚙ Parámetros'!B24,"ALTA PRIORIDAD",IF(C40>='⚙ Parámetros'!B25,"PRIORIDAD MEDIA",IF(C40>='⚙ Parámetros'!B26,"BAJA PRIORIDAD","DESCARTAR"))))),"Sin evaluar"),"Sin evaluar") -> Sin evaluar
B42: Horas estimadas | D42: Pool | E42: =IF(C42="","Sin estimar",IF(C42<'⚙ Parámetros'!B29,"🟢 Corto",IF(C42<'⚙ Parámetros'!B30,"🟡 Medio","🔴 Largo"))) -> Sin estimar

Sheet 📊 Cartera
A1: mesoestetic® · Cartera de Proyectos — Scoring Automático
A2: Introduce notas 1–10 en las columnas D–Y (en azul) · El scoring se calcula automáticamente · Parámetros configurables en ⚙ Parámetros
A4: # | B4: Nombre del proyecto | C4: Área | D4: Sponsor | E4: Fecha solicitud | F4: D1 | H4: D2 | J4: D2 | L4: D3 | N4: D3 | P4: D4 | R4: D4 | T4: D5 | V4: D5 | W4: D6 | Y4: D6 | AA4: D1 | AB4: D1 | AC4: D2 | AD4: D3 | AE4: D4 | AF4: D5 | AG4: D6 | AH4: Base | AI4: Aging | AJ4: FINAL | AK4: Clasificación | AL4: D1≥8 | AM4: Horas | AN4: Pool
A5: # | B5: Nombre | C5: Área | D5: Sponsor | E5: Fecha | F5: R.legal | G5: PRL | H5: Reput. | I5: Reg. | J5: Consejo | K5: Int. | L5: I+D | M5: Urg. | N5: Ingr. | O5: Ahorro | P5: ROI | Q5: Cal. | R5: TRL | S5: Integr. | T5: Esc. | U5: GDPR | V5: Cap.IT | W5: Cambio | X5: TtV | Y5: Emp. | Z5: ESG | AA5: Form. | AB5: D1 | AC5: D2 | AD5: D3 | AE5: D4 | AF5: D5 | AG5: D6 | AH5: Base | AI5: Aging | AJ5: Final | AK5: Clasif. | AL5: D1≥8 | AM5: Horas | AN5: Pool
A6: 1 | B6: MPG-FIN-006_01 Nuevas necesidades de BLOQUEO de clientes y de integraición CYC | C6: Finanzas y control | D6: Fernando García | E6: 23/12/2024 | F6: 9 | G6: 5 | H6: 9 | I6: 5 | J6: 7 | K6: 1 | L6: 8 | M6: 3 | N6: 7 | O6: 6 | P6: 7 | Q6: 6 | R6: 9 | S6: 9 | T6: 5 | U6: 5 | V6: 8 | W6: 6 | X6: 3 | Y6: 9 | Z6: 2 | AA6: 5 | AB6: 7 | AC6: =IFERROR((35/100*MAX('⚙ Parámetros'!D16/(1+2^(-'⚙ Parámetros'!C16*(J6-'⚙ Parámetros'!B16))),'⚙ Parámetros'!G16/(1+2^(-'⚙ Parámetros'!F16*(J6-'⚙ Parámetros'!E16))),1)*J6+25/100*MAX('⚙ Parámetros'!D16/(1+2^(-'⚙ Parámetros'!C16*(K6-'⚙ Parámetros'!B16))),'⚙ Parámetros'!G16/(1+2^(-'⚙ Parámetros'!F16*(K6-'⚙ Parámetros'!E16))),1)*K6+20/100*MAX('⚙ Parámetros'!D16/(1+2^(-'⚙ Parámetros'!C16*(L6-'⚙ Parámetros'!B16))),'⚙ Parámetros'!G16/(1+2^(-'⚙ Parámetros'!F16*(L6-'⚙ Parámetros'!E16))),1)*L6+20/100*MAX('⚙ Parámetros'!D16/(1+2^(-'⚙ Parámetros'!C16*(M6-'⚙ Parámetros'!B16))),'⚙ Parámetros'!G16/(1+2^(-'⚙ Parámetros'!F16*(M6-'⚙ Parámetros'!E16))),1)*M6)/(35/100*MAX('⚙ Parámetros'!D16/(1+2^(-'⚙ Parámetros'!C16*(J6-'⚙ Parámetros'!B16))),'⚙ Parámetros'!G16/(1+2^(-'⚙ Parámetros'!F16*(J6-'⚙ Parámetros'!E16))),1)+25/100*MAX('⚙ Parámetros'!D16/(1+2^(-'⚙ Parámetros'!C16*(K6-'⚙ Parámetros'!B16))),'⚙ Parámetros'!G16/(1+2^(-'⚙ Parámetros'!F16*(K6-'⚙ Parámetros'!E16))),1)+20/100*MAX('⚙ Parámetros'!D16/(1+2^(-'⚙ Parámetros'!C16*(L6-'⚙ Parámetros'!B16))),'⚙ Parámetros'!G16/(1+2^(-'⚙ Parámetros'!F16*(L6-'⚙ Parámetros'!E16))),1)+20/100*MAX('⚙ Parámetros'!D16/(1+2^(-'⚙ Parámetros'!C16*(M6-'⚙ Parámetros'!B16))),'⚙ Parámetros'!G16/(1+2^(-'⚙ Parámetros'!F16*(M6-'⚙ Parámetros'!E16))),1)),0) -> 6.3868613 | AD6: =IFERROR((30/100*MAX('⚙ Parámetros'!D17/(1+2^(-'⚙ Parámetros'!C17*(N6-'⚙ Parámetros'!B17))),'⚙ Parámetros'!G17/(1+2^(-'⚙ Parámetros'!F17*(N6-'⚙ Parámetros'!E17))),1)*N6+25/100*MAX('⚙ Parámetros'!D17/(1+2^(-'⚙ Parámetros'!C17*(O6-'⚙ Parámetros'!B17))),'⚙ Parámetros'!G17/(1+2^(-'⚙ Parámetros'!F17*(O6-'⚙ Parámetros'!E17))),1)*O6+25/100*MAX('⚙ Parámetros'!D17/(1+2^(-'⚙ Parámetros'!C17*(P6-'⚙ Parámetros'!B17))),'⚙ Parámetros'!G17/(1+2^(-'⚙ Parámetros'!F17*(P6-'⚙ Parámetros'!E17))),1)*P6+20/100*MAX('⚙ Parámetros'!D17/(1+2^(-'⚙ Parámetros'!C17*(Q6-'⚙ Parámetros'!B17))),'⚙ Parámetros'!G17/(1+2^(-'⚙ Parámetros'!F17*(Q6-'⚙ Parámetros'!E17))),1)*Q6)/(30/100*MAX('⚙ Parámetros'!D17/(1+2^(-'⚙ Parámetros'!C17*(N6-'⚙ Parámetros'!B17))),'⚙ Parámetros'!G17/(1+2^(-'⚙ Parámetros'!F17*(N6-'⚙ Parámetros'!E17))),1)+25/100*MAX('⚙ Parámetros'!D17/(1+2^(-'⚙ Parámetros'!C17*(O6-'⚙ Parámetros'!B17))),'⚙ Parámetros'!G17/(1+2^(-'⚙ Parámetros'!F17*(O6-'⚙ Parámetros'!E17))),1)+25/100*MAX('⚙ Parámetros'!D17/(1+2^(-'⚙ Parámetros'!C17*(P6-'⚙ Parámetros'!B17))),'⚙ Parámetros'!G17/(1+2^(-'⚙ Parámetros'!F17*(P6-'⚙ Parámetros'!E17))),1)+20/100*MAX('⚙ Parámetros'!D17/(1+2^(-'⚙ Parámetros'!C17*(Q6-'⚙ Parámetros'!B17))),'⚙ Parámetros'!G17/(1+2^(-'⚙ Parámetros'!F17*(Q6-'⚙ Parámetros'!E17))),1)),0) -> 6.5759162 | AE6: =IFERROR((30/100*MAX('⚙ Parámetros'!D18/(1+2^(-'⚙ Parámetros'!C18*(R6-'⚙ Parámetros'!B18))),'⚙ Parámetros'!G18/(1+2^(-'⚙ Parámetros'!F18*(R6-'⚙ Parámetros'!E18))),1)*R6+30/100*MAX('⚙ Parámetros'!D18/(1+2^(-'⚙ Parámetros'!C18*(S6-'⚙ Parámetros'!B18))),'⚙ Parámetros'!G18/(1+2^(-'⚙ Parámetros'!F18*(S6-'⚙ Parámetros'!E18))),1)*S6+20/100*MAX('⚙ Parámetros'!D18/(1+2^(-'⚙ Parámetros'!C18*(T6-'⚙ Parámetros'!B18))),'⚙ Parámetros'!G18/(1+2^(-'⚙ Parámetros'!F18*(T6-'⚙ Parámetros'!E18))),1)*T6+20/100*MAX('⚙ Parámetros'!D18/(1+2^(-'⚙ Parámetros'!C18*(U6-'⚙ Parámetros'!B18))),'⚙ Parámetros'!G18/(1+2^(-'⚙ Parámetros'!F18*(U6-'⚙ Parámetros'!E18))),1)*U6)/(30/100*MAX('⚙ Parámetros'!D18/(1+2^(-'⚙ Parámetros'!C18*(R6-'⚙ Parámetros'!B18))),'⚙ Parámetros'!G18/(1+2^(-'⚙ Parámetros'!F18*(R6-'⚙ Parámetros'!E18))),1)+30/100*MAX('⚙ Parámetros'!D18/(1+2^(-'⚙ Parámetros'!C18*(S6-'⚙ Parámetros'!B18))),'⚙ Parámetros'!G18/(1+2^(-'⚙ Parámetros'!F18*(S6-'⚙ Parámetros'!E18))),1)+20/100*MAX('⚙ Parámetros'!D18/(1+2^(-'⚙ Parámetros'!C18*(T6-'⚙ Parámetros'!B18))),'⚙ Parámetros'!G18/(1+2^(-'⚙ Parámetros'!F18*(T6-'⚙ Parámetros'!E18))),1)+20/100*MAX('⚙ Parámetros'!D18/(1+2^(-'⚙ Parámetros'!C18*(U6-'⚙ Parámetros'!B18))),'⚙ Parámetros'!G18/(1+2^(-'⚙ Parámetros'!F18*(U6-'⚙ Parámetros'!E18))),1)),0) -> 8.180106 | AF6: =IFERROR((30/100*MAX('⚙ Parámetros'!D19/(1+2^(-'⚙ Parámetros'!C19*(V6-'⚙ Parámetros'!B19))),'⚙ Parámetros'!G19/(1+2^(-'⚙ Parámetros'!F19*(V6-'⚙ Parámetros'!E19))),1)*V6+35/100*MAX('⚙ Parámetros'!D19/(1+2^(-'⚙ Parámetros'!C19*(W6-'⚙ Parámetros'!B19))),'⚙ Parámetros'!G19/(1+2^(-'⚙ Parámetros'!F19*(W6-'⚙ Parámetros'!E19))),1)*W6+35/100*MAX('⚙ Parámetros'!D19/(1+2^(-'⚙ Parámetros'!C19*(X6-'⚙ Parámetros'!B19))),'⚙ Parámetros'!G19/(1+2^(-'⚙ Parámetros'!F19*(X6-'⚙ Parámetros'!E19))),1)*X6)/(30/100*MAX('⚙ Parámetros'!D19/(1+2^(-'⚙ Parámetros'!C19*(V6-'⚙ Parámetros'!B19))),'⚙ Parámetros'!G19/(1+2^(-'⚙ Parámetros'!F19*(V6-'⚙ Parámetros'!E19))),1)+35/100*MAX('⚙ Parámetros'!D19/(1+2^(-'⚙ Parámetros'!C19*(W6-'⚙ Parámetros'!B19))),'⚙ Parámetros'!G19/(1+2^(-'⚙ Parámetros'!F19*(W6-'⚙ Parámetros'!E19))),1)+35/100*MAX('⚙ Parámetros'!D19/(1+2^(-'⚙ Parámetros'!C19*(X6-'⚙ Parámetros'!B19))),'⚙ Parámetros'!G19/(1+2^(-'⚙ Parámetros'!F19*(X6-'⚙ Parámetros'!E19))),1)),0) -> 6.46875 | AG6: =IFERROR((35/100*MAX('⚙ Parámetros'!D20/(1+2^(-'⚙ Parámetros'!C20*(Y6-'⚙ Parámetros'!B20))),'⚙ Parámetros'!G20/(1+2^(-'⚙ Parámetros'!F20*(Y6-'⚙ Parámetros'!E20))),1)*Y6+35/100*MAX('⚙ Parámetros'!D20/(1+2^(-'⚙ Parámetros'!C20*(Z6-'⚙ Parámetros'!B20))),'⚙ Parámetros'!G20/(1+2^(-'⚙ Parámetros'!F20*(Z6-'⚙ Parámetros'!E20))),1)*Z6+30/100*MAX('⚙ Parámetros'!D20/(1+2^(-'⚙ Parámetros'!C20*(AA6-'⚙ Parámetros'!B20))),'⚙ Parámetros'!G20/(1+2^(-'⚙ Parámetros'!F20*(AA6-'⚙ Parámetros'!E20))),1)*AA6)/(35/100*MAX('⚙ Parámetros'!D20/(1+2^(-'⚙ Parámetros'!C20*(Y6-'⚙ Parámetros'!B20))),'⚙ Parámetros'!G20/(1+2^(-'⚙ Parámetros'!F20*(Y6-'⚙ Parámetros'!E20))),1)+35/100*MAX('⚙ Parámetros'!D20/(1+2^(-'⚙ Parámetros'!C20*(Z6-'⚙ Parámetros'!B20))),'⚙ Parámetros'!G20/(1+2^(-'⚙ Parámetros'!F20*(Z6-'⚙ Parámetros'!E20))),1)+30/100*MAX('⚙ Parámetros'!D20/(1+2^(-'⚙ Parámetros'!C20*(AA6-'⚙ Parámetros'!B20))),'⚙ Parámetros'!G20/(1+2^(-'⚙ Parámetros'!F20*(AA6-'⚙ Parámetros'!E20))),1)),0) -> 7.1162791 | AH6: =('⚙ Parámetros'!B5/100*AB6+'⚙ Parámetros'!B6/100*AC6+'⚙ Parámetros'!B7/100*AD6+'⚙ Parámetros'!B8/100*AE6+'⚙ Parámetros'!B9/100*AF6+'⚙ Parámetros'!B10/100*AG6) -> 6.8903456 | AI6: =MIN(1+MAX(0,TODAY()-DATE(2024,12,23))/365*'⚙ Parámetros'!B33,'⚙ Parámetros'!B34) -> 1.220274 | AJ6: =IFERROR(MIN(AH6*AI6,10),0) -> 8.4081093 | AK6: =IF(AB6>='⚙ Parámetros'!B23,"⚑ AUTO-PRIOR.(D1≥8)",IF(AJ6>='⚙ Parámetros'!B23,"PRIORITARIO",IF(AJ6>='⚙ Parámetros'!B24,"ALTA PRIORIDAD",IF(AJ6>='⚙ Parámetros'!B25,"PRIORIDAD MEDIA",IF(AJ6>='⚙ Parámetros'!B26,"BAJA PRIORIDAD","DESCARTAR"))))) -> ALTA PRIORIDAD | AL6: =IF(AB6>=8,"SÍ ⚑","—") -> — | AM6: 50 | AN6: =IF(AM6="","—",IF(AM6<'⚙ Parámetros'!B29,"🟢 Corto",IF(AM6<'⚙ Parámetros'!B30,"🟡 Medio","🔴 Largo"))) -> 🟡 Medio
A7: 2 | B7: MPG-LOG-065 Integración almacén DSV | C7: Supply chain y logística | D7: Marc Bometon | E7: 21/04/2026 | F7: 6 | G7: 5 | H7: 5 | I7: 5 | J7: 10 | K7: 8 | L7: 8 | M7: 9 | N7: 8 | O7: 8 | P7: 1 | Q7: 8 | R7: 6 | S7: 5 | T7: 5 | U7: 5 | V7: 5 | W7: 6 | X7: 3 | Y7: 5 | Z7: 2 | AA7: 8 | AB7: =IFERROR((30/100*MAX('⚙ Parámetros'!D15/(1+2^(-'⚙ Parámetros'!C15*(F7-'⚙ Parámetros'!B15))),'⚙ Parámetros'!G15/(1+2^(-'⚙ Parámetros'!F15*(F7-'⚙ Parámetros'!E15))),1)*F7+30/100*MAX('⚙ Parámetros'!D15/(1+2^(-'⚙ Parámetros'!C15*(G7-'⚙ Parámetros'!B15))),'⚙ Parámetros'!G15/(1+2^(-'⚙ Parámetros'!F15*(G7-'⚙ Parámetros'!E15))),1)*G7+20/100*MAX('⚙ Parámetros'!D15/(1+2^(-'⚙ Parámetros'!C15*(H7-'⚙ Parámetros'!B15))),'⚙ Parámetros'!G15/(1+2^(-'⚙ Parámetros'!F15*(H7-'⚙ Parámetros'!E15))),1)*H7+20/100*MAX('⚙ Parámetros'!D15/(1+2^(-'⚙ Parámetros'!C15*(I7-'⚙ Parámetros'!B15))),'⚙ Parámetros'!G15/(1+2^(-'⚙ Parámetros'!F15*(I7-'⚙ Parámetros'!E15))),1)*I7)/(30/100*MAX('⚙ Parámetros'!D15/(1+2^(-'⚙ Parámetros'!C15*(F7-'⚙ Parámetros'!B15))),'⚙ Parámetros'!G15/(1+2^(-'⚙ Parámetros'!F15*(F7-'⚙ Parámetros'!E15))),1)+30/100*MAX('⚙ Parámetros'!D15/(1+2^(-'⚙ Parámetros'!C15*(G7-'⚙ Parámetros'!B15))),'⚙ Parámetros'!G15/(1+2^(-'⚙ Parámetros'!F15*(G7-'⚙ Parámetros'!E15))),1)+20/100*MAX('⚙ Parámetros'!D15/(1+2^(-'⚙ Parámetros'!C15*(H7-'⚙ Parámetros'!B15))),'⚙ Parámetros'!G15/(1+2^(-'⚙ Parámetros'!F15*(H7-'⚙ Parámetros'!E15))),1)+20/100*MAX('⚙ Parámetros'!D15/(1+2^(-'⚙ Parámetros'!C15*(I7-'⚙ Parámetros'!B15))),'⚙ Parámetros'!G15/(1+2^(-'⚙ Parámetros'!F15*(I7-'⚙ Parámetros'!E15))),1)),0) -> 5.3253012 | AC7: =IFERROR((35/100*MAX('⚙ Parámetros'!D16/(1+2^(-'⚙ Parámetros'!C16*(J7-'⚙ Parámetros'!B16))),'⚙ Parámetros'!G16/(1+2^(-'⚙ Parámetros'!F16*(J7-'⚙ Parámetros'!E16))),1)*J7+25/100*MAX('⚙ Parámetros'!D16/(1+2^(-'⚙ Parámetros'!C16*(K7-'⚙ Parámetros'!B16))),'⚙ Parámetros'!G16/(1+2^(-'⚙ Parámetros'!F16*(K7-'⚙ Parámetros'!E16))),1)*K7+20/100*MAX('⚙ Parámetros'!D16/(1+2^(-'⚙ Parámetros'!C16*(L7-'⚙ Parámetros'!B16))),'⚙ Parámetros'!G16/(1+2^(-'⚙ Parámetros'!F16*(L7-'⚙ Parámetros'!E16))),1)*L7+20/100*MAX('⚙ Parámetros'!D16/(1+2^(-'⚙ Parámetros'!C16*(M7-'⚙ Parámetros'!B16))),'⚙ Parámetros'!G16/(1+2^(-'⚙ Parámetros'!F16*(M7-'⚙ Parámetros'!E16))),1)*M7)/(35/100*MAX('⚙ Parámetros'!D16/(1+2^(-'⚙ Parámetros'!C16*(J7-'⚙ Parámetros'!B16))),'⚙ Parámetros'!G16/(1+2^(-'⚙ Parámetros'!F16*(J7-'⚙ Parámetros'!E16))),1)+25/100*MAX('⚙ Parámetros'!D16/(1+2^(-'⚙ Parámetros'!C16*(K7-'⚙ Parámetros'!B16))),'⚙ Parámetros'!G16/(1+2^(-'⚙ Parámetros'!F16*(K7-'⚙ Parámetros'!E16))),1)+20/100*MAX('⚙ Parámetros'!D16/(1+2^(-'⚙ Parámetros'!C16*(L7-'⚙ Parámetros'!B16))),'⚙ Parámetros'!G16/(1+2^(-'⚙ Parámetros'!F16*(L7-'⚙ Parámetros'!E16))),1)+20/100*MAX('⚙ Parámetros'!D16/(1+2^(-'⚙ Parámetros'!C16*(M7-'⚙ Parámetros'!B16))),'⚙ Parámetros'!G16/(1+2^(-'⚙ Parámetros'!F16*(M7-'⚙ Parámetros'!E16))),1)),0) -> 9.1461507 | AD7: =IFERROR((30/100*MAX('⚙ Parámetros'!D17/(1+2^(-'⚙ Parámetros'!C17*(N7-'⚙ Parámetros'!B17))),'⚙ Parámetros'!G17/(1+2^(-'⚙ Parámetros'!F17*(N7-'⚙ Parámetros'!E17))),1)*N7+25/100*MAX('⚙ Parámetros'!D17/(1+2^(-'⚙ Parámetros'!C17*(O7-'⚙ Parámetros'!B17))),'⚙ Parámetros'!G17/(1+2^(-'⚙ Parámetros'!F17*(O7-'⚙ Parámetros'!E17))),1)*O7+25/100*MAX('⚙ Parámetros'!D17/(1+2^(-'⚙ Parámetros'!C17*(P7-'⚙ Parámetros'!B17))),'⚙ Parámetros'!G17/(1+2^(-'⚙ Parámetros'!F17*(P7-'⚙ Parámetros'!E17))),1)*P7+20/100*MAX('⚙ Parámetros'!D17/(1+2^(-'⚙ Parámetros'!C17*(Q7-'⚙ Parámetros'!B17))),'⚙ Parámetros'!G17/(1+2^(-'⚙ Parámetros'!F17*(Q7-'⚙ Parámetros'!E17))),1)*Q7)/(30/100*MAX('⚙ Parámetros'!D17/(1+2^(-'⚙ Parámetros'!C17*(N7-'⚙ Parámetros'!B17))),'⚙ Parámetros'!G17/(1+2^(-'⚙ Parámetros'!F17*(N7-'⚙ Parámetros'!E17))),1)+25/100*MAX('⚙ Parámetros'!D17/(1+2^(-'⚙ Parámetros'!C17*(O7-'⚙ Parámetros'!B17))),'⚙ Parámetros'!G17/(1+2^(-'⚙ Parámetros'!F17*(O7-'⚙ Parámetros'!E17))),1)+25/100*MAX('⚙ Parámetros'!D17/(1+2^(-'⚙ Parámetros'!C17*(P7-'⚙ Parámetros'!B17))),'⚙ Parámetros'!G17/(1+2^(-'⚙ Parámetros'!F17*(P7-'⚙ Parámetros'!E17))),1)+20/100*MAX('⚙ Parámetros'!D17/(1+2^(-'⚙ Parámetros'!C17*(Q7-'⚙ Parámetros'!B17))),'⚙ Parámetros'!G17/(1+2^(-'⚙ Parámetros'!F17*(Q7-'⚙ Parámetros'!E17))),1)),0) -> 7.4615385 | AE7: =IFERROR((30/100*MAX('⚙ Parámetros'!D18/(1+2^(-'⚙ Parámetros'!C18*(R7-'⚙ Parámetros'!B18))),'⚙ Parámetros'!G18/(1+2^(-'⚙ Parámetros'!F18*(R7-'⚙ Parámetros'!E18))),1)*R7+30/100*MAX('⚙ Parámetros'!D18/(1+2^(-'⚙ Parámetros'!C18*(S7-'⚙ Parámetros'!B18))),'⚙ Parámetros'!G18/(1+2^(-'⚙ Parámetros'!F18*(S7-'⚙ Parámetros'!E18))),1)*S7+20/100*MAX('⚙ Parámetros'!D18/(1+2^(-'⚙ Parámetros'!C18*(T7-'⚙ Parámetros'!B18))),'⚙ Parámetros'!G18/(1+2^(-'⚙ Parámetros'!F18*(T7-'⚙ Parámetros'!E18))),1)*T7+20/100*MAX('⚙ Parámetros'!D18/(1+2^(-'⚙ Parámetros'!C18*(U7-'⚙ Parámetros'!B18))),'⚙ Parámetros'!G18/(1+2^(-'⚙ Parámetros'!F18*(U7-'⚙ Parámetros'!E18))),1)*U7)/(30/100*MAX('⚙ Parámetros'!D18/(1+2^(-'⚙ Parámetros'!C18*(R7-'⚙ Parámetros'!B18))),'⚙ Parámetros'!G18/(1+2^(-'⚙ Parámetros'!F18*(R7-'⚙ Parámetros'!E18))),1)+30/100*MAX('⚙ Parámetros'!D18/(1+2^(-'⚙ Parámetros'!C18*(S7-'⚙ Parámetros'!B18))),'⚙ Parámetros'!G18/(1+2^(-'⚙ Parámetros'!F18*(S7-'⚙ Parámetros'!E18))),1)+20/100*MAX('⚙ Parámetros'!D18/(1+2^(-'⚙ Parámetros'!C18*(T7-'⚙ Parámetros'!B18))),'⚙ Parámetros'!G18/(1+2^(-'⚙ Parámetros'!F18*(T7-'⚙ Parámetros'!E18))),1)+20/100*MAX('⚙ Parámetros'!D18/(1+2^(-'⚙ Parámetros'!C18*(U7-'⚙ Parámetros'!B18))),'⚙ Parámetros'!G18/(1+2^(-'⚙ Parámetros'!F18*(U7-'⚙ Parámetros'!E18))),1)),0) -> 5.3396226 | AF7: =IFERROR((30/100*MAX('⚙ Parámetros'!D19/(1+2^(-'⚙ Parámetros'!C19*(V7-'⚙ Parámetros'!B19))),'⚙ Parámetros'!G19/(1+2^(-'⚙ Parámetros'!F19*(V7-'⚙ Parámetros'!E19))),1)*V7+35/100*MAX('⚙ Parámetros'!D19/(1+2^(-'⚙ Parámetros'!C19*(W7-'⚙ Parámetros'!B19))),'⚙ Parámetros'!G19/(1+2^(-'⚙ Parámetros'!F19*(W7-'⚙ Parámetros'!E19))),1)*W7+35/100*MAX('⚙ Parámetros'!D19/(1+2^(-'⚙ Parámetros'!C19*(X7-'⚙ Parámetros'!B19))),'⚙ Parámetros'!G19/(1+2^(-'⚙ Parámetros'!F19*(X7-'⚙ Parámetros'!E19))),1)*X7)/(30/100*MAX('⚙ Parámetros'!D19/(1+2^(-'⚙ Parámetros'!C19*(V7-'⚙ Parámetros'!B19))),'⚙ Parámetros'!G19/(1+2^(-'⚙ Parámetros'!F19*(V7-'⚙ Parámetros'!E19))),1)+35/100*MAX('⚙ Parámetros'!D19/(1+2^(-'⚙ Parámetros'!C19*(W7-'⚙ Parámetros'!B19))),'⚙ Parámetros'!G19/(1+2^(-'⚙ Parámetros'!F19*(W7-'⚙ Parámetros'!E19))),1)+35/100*MAX('⚙ Parámetros'!D19/(1+2^(-'⚙ Parámetros'!C19*(X7-'⚙ Parámetros'!B19))),'⚙ Parámetros'!G19/(1+2^(-'⚙ Parámetros'!F19*(X7-'⚙ Parámetros'!E19))),1)),0) -> 5.0782123 | AG7: =IFERROR((35/100*MAX('⚙ Parámetros'!D20/(1+2^(-'⚙ Parámetros'!C20*(Y7-'⚙ Parámetros'!B20))),'⚙ Parámetros'!G20/(1+2^(-'⚙ Parámetros'!F20*(Y7-'⚙ Parámetros'!E20))),1)*Y7+35/100*MAX('⚙ Parámetros'!D20/(1+2^(-'⚙ Parámetros'!C20*(Z7-'⚙ Parámetros'!B20))),'⚙ Parámetros'!G20/(1+2^(-'⚙ Parámetros'!F20*(Z7-'⚙ Parámetros'!E20))),1)*Z7+30/100*MAX('⚙ Parámetros'!D20/(1+2^(-'⚙ Parámetros'!C20*(AA7-'⚙ Parámetros'!B20))),'⚙ Parámetros'!G20/(1+2^(-'⚙ Parámetros'!F20*(AA7-'⚙ Parámetros'!E20))),1)*AA7)/(35/100*MAX('⚙ Parámetros'!D20/(1+2^(-'⚙ Parámetros'!C20*(Y7-'⚙ Parámetros'!B20))),'⚙ Parámetros'!G20/(1+2^(-'⚙ Parámetros'!F20*(Y7-'⚙ Parámetros'!E20))),1)+35/100*MAX('⚙ Parámetros'!D20/(1+2^(-'⚙ Parámetros'!C20*(Z7-'⚙ Parámetros'!B20))),'⚙ Parámetros'!G20/(1+2^(-'⚙ Parámetros'!F20*(Z7-'⚙ Parámetros'!E20))),1)+30/100*MAX('⚙ Parámetros'!D20/(1+2^(-'⚙ Parámetros'!C20*(AA7-'⚙ Parámetros'!B20))),'⚙ Parámetros'!G20/(1+2^(-'⚙ Parámetros'!F20*(AA7-'⚙ Parámetros'!E20))),1)),0) -> 5.961165 | AH7: =('⚙ Parámetros'!B5/100*AB7+'⚙ Parámetros'!B6/100*AC7+'⚙ Parámetros'!B7/100*AD7+'⚙ Parámetros'!B8/100*AE7+'⚙ Parámetros'!B9/100*AF7+'⚙ Parámetros'!B10/100*AG7) -> 6.5445973 | AI7: =MIN(1+MAX(0,TODAY()-DATE(2026,4,21))/365*'⚙ Parámetros'!B33,'⚙ Parámetros'!B34) -> 1.0213699 | AJ7: =IFERROR(MIN(AH7*AI7,10),0) -> 6.6844545 | AK7: =IF(AB7>='⚙ Parámetros'!B23,"⚑ AUTO-PRIOR.(D1≥8)",IF(AJ7>='⚙ Parámetros'!B23,"PRIORITARIO",IF(AJ7>='⚙ Parámetros'!B24,"ALTA PRIORIDAD",IF(AJ7>='⚙ Parámetros'!B25,"PRIORIDAD MEDIA",IF(AJ7>='⚙ Parámetros'!B26,"BAJA PRIORIDAD","DESCARTAR"))))) -> PRIORIDAD MEDIA | AL7: =IF(AB7>=8,"SÍ ⚑","—") -> — | AM7: 250 | AN7: =IF(AM7="","—",IF(AM7<'⚙ Parámetros'!B29,"🟢 Corto",IF(AM7<'⚙ Parámetros'!B30,"🟡 Medio","🔴 Largo"))) -> 🔴 Largo
A8: 4 | B8: MPG-CAL-018 COA - Firma electronica | C8: Regulatorio y calidad | D8: Marc Bometon | E8: 14/01/2026 | F8: 9 | G8: 5 | H8: 7 | I8: 8 | J8: 1 | K8: 1 | L8: 8 | M8: 3 | N8: 7 | O8: 1 | P8: 1 | Q8: 8 | R8: 5 | S8: 5 | T8: 5 | U8: 8 | V8: 8 | W8: 6 | X8: 9 | Y8: 4 | Z8: 2 | AA8: 5 | AB8: =IFERROR((30/100*MAX('⚙ Parámetros'!D15/(1+2^(-'⚙ Parámetros'!C15*(F8-'⚙ Parámetros'!B15))),'⚙ Parámetros'!G15/(1+2^(-'⚙ Parámetros'!F15*(F8-'⚙ Parámetros'!E15))),1)*F8+30/100*MAX('⚙ Parámetros'!D15/(1+2^(-'⚙ Parámetros'!C15*(G8-'⚙ Parámetros'!B15))),'⚙ Parámetros'!G15/(1+2^(-'⚙ Parámetros'!F15*(G8-'⚙ Parámetros'!E15))),1)*G8+20/100*MAX('⚙ Parámetros'!D15/(1+2^(-'⚙ Parámetros'!C15*(H8-'⚙ Parámetros'!B15))),'⚙ Parámetros'!G15/(1+2^(-'⚙ Parámetros'!F15*(H8-'⚙ Parámetros'!E15))),1)*H8+20/100*MAX('⚙ Parámetros'!D15/(1+2^(-'⚙ Parámetros'!C15*(I8-'⚙ Parámetros'!B15))),'⚙ Parámetros'!G15/(1+2^(-'⚙ Parámetros'!F15*(I8-'⚙ Parámetros'!E15))),1)*I8)/(30/100*MAX('⚙ Parámetros'!D15/(1+2^(-'⚙ Parámetros'!C15*(F8-'⚙ Parámetros'!B15))),'⚙ Parámetros'!G15/(1+2^(-'⚙ Parámetros'!F15*(F8-'⚙ Parámetros'!E15))),1)+30/100*MAX('⚙ Parámetros'!D15/(1+2^(-'⚙ Parámetros'!C15*(G8-'⚙ Parámetros'!B15))),'⚙ Parámetros'!G15/(1+2^(-'⚙ Parámetros'!F15*(G8-'⚙ Parámetros'!E15))),1)+20/100*MAX('⚙ Parámetros'!D15/(1+2^(-'⚙ Parámetros'!C15*(H8-'⚙ Parámetros'!B15))),'⚙ Parámetros'!G15/(1+2^(-'⚙ Parámetros'!F15*(H8-'⚙ Parámetros'!E15))),1)+20/100*MAX('⚙ Parámetros'!D15/(1+2^(-'⚙ Parámetros'!C15*(I8-'⚙ Parámetros'!B15))),'⚙ Parámetros'!G15/(1+2^(-'⚙ Parámetros'!F15*(I8-'⚙ Parámetros'!E15))),1)),0) -> 8.0375247 | AC8: =IFERROR((35/100*MAX('⚙ Parámetros'!D16/(1+2^(-'⚙ Parámetros'!C16*(J8-'⚙ Parámetros'!B16))),'⚙ Parámetros'!G16/(1+2^(-'⚙ Parámetros'!F16*(J8-'⚙ Parámetros'!E16))),1)*J8+25/100*MAX('⚙ Parámetros'!D16/(1+2^(-'⚙ Parámetros'!C16*(K8-'⚙ Parámetros'!B16))),'⚙ Parámetros'!G16/(1+2^(-'⚙ Parámetros'!F16*(K8-'⚙ Parámetros'!E16))),1)*K8+20/100*MAX('⚙ Parámetros'!D16/(1+2^(-'⚙ Parámetros'!C16*(L8-'⚙ Parámetros'!B16))),'⚙ Parámetros'!G16/(1+2^(-'⚙ Parámetros'!F16*(L8-'⚙ Parámetros'!E16))),1)*L8+20/100*MAX('⚙ Parámetros'!D16/(1+2^(-'⚙ Parámetros'!C16*(M8-'⚙ Parámetros'!B16))),'⚙ Parámetros'!G16/(1+2^(-'⚙ Parámetros'!F16*(M8-'⚙ Parámetros'!E16))),1)*M8)/(35/100*MAX('⚙ Parámetros'!D16/(1+2^(-'⚙ Parámetros'!C16*(J8-'⚙ Parámetros'!B16))),'⚙ Parámetros'!G16/(1+2^(-'⚙ Parámetros'!F16*(J8-'⚙ Parámetros'!E16))),1)+25/100*MAX('⚙ Parámetros'!D16/(1+2^(-'⚙ Parámetros'!C16*(K8-'⚙ Parámetros'!B16))),'⚙ Parámetros'!G16/(1+2^(-'⚙ Parámetros'!F16*(K8-'⚙ Parámetros'!E16))),1)+20/100*MAX('⚙ Parámetros'!D16/(1+2^(-'⚙ Parámetros'!C16*(L8-'⚙ Parámetros'!B16))),'⚙ Parámetros'!G16/(1+2^(-'⚙ Parámetros'!F16*(L8-'⚙ Parámetros'!E16))),1)+20/100*MAX('⚙ Parámetros'!D16/(1+2^(-'⚙ Parámetros'!C16*(M8-'⚙ Parámetros'!B16))),'⚙ Parámetros'!G16/(1+2^(-'⚙ Parámetros'!F16*(M8-'⚙ Parámetros'!E16))),1)),0) -> 4.9411765 | AD8: =IFERROR((30/100*MAX('⚙ Parámetros'!D17/(1+2^(-'⚙ Parámetros'!C17*(N8-'⚙ Parámetros'!B17))),'⚙ Parámetros'!G17/(1+2^(-'⚙ Parámetros'!F17*(N8-'⚙ Parámetros'!E17))),1)*N8+25/100*MAX('⚙ Parámetros'!D17/(1+2^(-'⚙ Parámetros'!C17*(O8-'⚙ Parámetros'!B17))),'⚙ Parámetros'!G17/(1+2^(-'⚙ Parámetros'!F17*(O8-'⚙ Parámetros'!E17))),1)*O8+25/100*MAX('⚙ Parámetros'!D17/(1+2^(-'⚙ Parámetros'!C17*(P8-'⚙ Parámetros'!B17))),'⚙ Parámetros'!G17/(1+2^(-'⚙ Parámetros'!F17*(P8-'⚙ Parámetros'!E17))),1)*P8+20/100*MAX('⚙ Parámetros'!D17/(1+2^(-'⚙ Parámetros'!C17*(Q8-'⚙ Parámetros'!B17))),'⚙ Parámetros'!G17/(1+2^(-'⚙ Parámetros'!F17*(Q8-'⚙ Parámetros'!E17))),1)*Q8)/(30/100*MAX('⚙ Parámetros'!D17/(1+2^(-'⚙ Parámetros'!C17*(N8-'⚙ Parámetros'!B17))),'⚙ Parámetros'!G17/(1+2^(-'⚙ Parámetros'!F17*(N8-'⚙ Parámetros'!E17))),1)+25/100*MAX('⚙ Parámetros'!D17/(1+2^(-'⚙ Parámetros'!C17*(O8-'⚙ Parámetros'!B17))),'⚙ Parámetros'!G17/(1+2^(-'⚙ Parámetros'!F17*(O8-'⚙ Parámetros'!E17))),1)+25/100*MAX('⚙ Parámetros'!D17/(1+2^(-'⚙ Parámetros'!C17*(P8-'⚙ Parámetros'!B17))),'⚙ Parámetros'!G17/(1+2^(-'⚙ Parámetros'!F17*(P8-'⚙ Parámetros'!E17))),1)+20/100*MAX('⚙ Parámetros'!D17/(1+2^(-'⚙ Parámetros'!C17*(Q8-'⚙ Parámetros'!B17))),'⚙ Parámetros'!G17/(1+2^(-'⚙ Parámetros'!F17*(Q8-'⚙ Parámetros'!E17))),1)),0) -> 5.952381 | AE8: =IFERROR((30/100*MAX('⚙ Parámetros'!D18/(1+2^(-'⚙ Parámetros'!C18*(R8-'⚙ Parámetros'!B18))),'⚙ Parámetros'!G18/(1+2^(-'⚙ Parámetros'!F18*(R8-'⚙ Parámetros'!E18))),1)*R8+30/100*MAX('⚙ Parámetros'!D18/(1+2^(-'⚙ Parámetros'!C18*(S8-'⚙ Parámetros'!B18))),'⚙ Parámetros'!G18/(1+2^(-'⚙ Parámetros'!F18*(S8-'⚙ Parámetros'!E18))),1)*S8+20/100*MAX('⚙ Parámetros'!D18/(1+2^(-'⚙ Parámetros'!C18*(T8-'⚙ Parámetros'!B18))),'⚙ Parámetros'!G18/(1+2^(-'⚙ Parámetros'!F18*(T8-'⚙ Parámetros'!E18))),1)*T8+20/100*MAX('⚙ Parámetros'!D18/(1+2^(-'⚙ Parámetros'!C18*(U8-'⚙ Parámetros'!B18))),'⚙ Parámetros'!G18/(1+2^(-'⚙ Parámetros'!F18*(U8-'⚙ Parámetros'!E18))),1)*U8)/(30/100*MAX('⚙ Parámetros'!D18/(1+2^(-'⚙ Parámetros'!C18*(R8-'⚙ Parámetros'!B18))),'⚙ Parámetros'!G18/(1+2^(-'⚙ Parámetros'!F18*(R8-'⚙ Parámetros'!E18))),1)+30/100*MAX('⚙ Parámetros'!D18/(1+2^(-'⚙ Parámetros'!C18*(S8-'⚙ Parámetros'!B18))),'⚙ Parámetros'!G18/(1+2^(-'⚙ Parámetros'!F18*(S8-'⚙ Parámetros'!E18))),1)+20/100*MAX('⚙ Parámetros'!D18/(1+2^(-'⚙ Parámetros'!C18*(T8-'⚙ Parámetros'!B18))),'⚙ Parámetros'!G18/(1+2^(-'⚙ Parámetros'!F18*(T8-'⚙ Parámetros'!E18))),1)+20/100*MAX('⚙ Parámetros'!D18/(1+2^(-'⚙ Parámetros'!C18*(U8-'⚙ Parámetros'!B18))),'⚙ Parámetros'!G18/(1+2^(-'⚙ Parámetros'!F18*(U8-'⚙ Parámetros'!E18))),1)),0) -> 5.9130435 | AF8: =IFERROR((30/100*MAX('⚙ Parámetros'!D19/(1+2^(-'⚙ Parámetros'!C19*(V8-'⚙ Parámetros'!B19))),'⚙ Parámetros'!G19/(1+2^(-'⚙ Parámetros'!F19*(V8-'⚙ Parámetros'!E19))),1)*V8+35/100*MAX('⚙ Parámetros'!D19/(1+2^(-'⚙ Parámetros'!C19*(W8-'⚙ Parámetros'!B19))),'⚙ Parámetros'!G19/(1+2^(-'⚙ Parámetros'!F19*(W8-'⚙ Parámetros'!E19))),1)*W8+35/100*MAX('⚙ Parámetros'!D19/(1+2^(-'⚙ Parámetros'!C19*(X8-'⚙ Parámetros'!B19))),'⚙ Parámetros'!G19/(1+2^(-'⚙ Parámetros'!F19*(X8-'⚙ Parámetros'!E19))),1)*X8)/(30/100*MAX('⚙ Parámetros'!D19/(1+2^(-'⚙ Parámetros'!C19*(V8-'⚙ Parámetros'!B19))),'⚙ Parámetros'!G19/(1+2^(-'⚙ Parámetros'!F19*(V8-'⚙ Parámetros'!E19))),1)+35/100*MAX('⚙ Parámetros'!D19/(1+2^(-'⚙ Parámetros'!C19*(W8-'⚙ Parámetros'!B19))),'⚙ Parámetros'!G19/(1+2^(-'⚙ Parámetros'!F19*(W8-'⚙ Parámetros'!E19))),1)+35/100*MAX('⚙ Parámetros'!D19/(1+2^(-'⚙ Parámetros'!C19*(X8-'⚙ Parámetros'!B19))),'⚙ Parámetros'!G19/(1+2^(-'⚙ Parámetros'!F19*(X8-'⚙ Parámetros'!E19))),1)),0) -> 8.0351483 | AG8: =IFERROR((35/100*MAX('⚙ Parámetros'!D20/(1+2^(-'⚙ Parámetros'!C20*(Y8-'⚙ Parámetros'!B20))),'⚙ Parámetros'!G20/(1+2^(-'⚙ Parámetros'!F20*(Y8-'⚙ Parámetros'!E20))),1)*Y8+35/100*MAX('⚙ Parámetros'!D20/(1+2^(-'⚙ Parámetros'!C20*(Z8-'⚙ Parámetros'!B20))),'⚙ Parámetros'!G20/(1+2^(-'⚙ Parámetros'!F20*(Z8-'⚙ Parámetros'!E20))),1)*Z8+30/100*MAX('⚙ Parámetros'!D20/(1+2^(-'⚙ Parámetros'!C20*(AA8-'⚙ Parámetros'!B20))),'⚙ Parámetros'!G20/(1+2^(-'⚙ Parámetros'!F20*(AA8-'⚙ Parámetros'!E20))),1)*AA8)/(35/100*MAX('⚙ Parámetros'!D20/(1+2^(-'⚙ Parámetros'!C20*(Y8-'⚙ Parámetros'!B20))),'⚙ Parámetros'!G20/(1+2^(-'⚙ Parámetros'!F20*(Y8-'⚙ Parámetros'!E20))),1)+35/100*MAX('⚙ Parámetros'!D20/(1+2^(-'⚙ Parámetros'!C20*(Z8-'⚙ Parámetros'!B20))),'⚙ Parámetros'!G20/(1+2^(-'⚙ Parámetros'!F20*(Z8-'⚙ Parámetros'!E20))),1)+30/100*MAX('⚙ Parámetros'!D20/(1+2^(-'⚙ Parámetros'!C20*(AA8-'⚙ Parámetros'!B20))),'⚙ Parámetros'!G20/(1+2^(-'⚙ Parámetros'!F20*(AA8-'⚙ Parámetros'!E20))),1)),0) -> 3.7272727 | AH8: =('⚙ Parámetros'!B5/100*AB8+'⚙ Parámetros'!B6/100*AC8+'⚙ Parámetros'!B7/100*AD8+'⚙ Parámetros'!B8/100*AE8+'⚙ Parámetros'!B9/100*AF8+'⚙ Parámetros'!B10/100*AG8) -> 6.4012308 | AI8: =MIN(1+MAX(0,TODAY()-DATE(2026,1,14))/365*'⚙ Parámetros'!B33,'⚙ Parámetros'!B34) -> 1.0612329 | AJ8: =IFERROR(MIN(AH8*AI8,10),0) -> 6.7931965 | AK8: =IF(AB8>='⚙ Parámetros'!B23,"⚑ AUTO-PRIOR.(D1≥8)",IF(AJ8>='⚙ Parámetros'!B23,"PRIORITARIO",IF(AJ8>='⚙ Parámetros'!B24,"ALTA PRIORIDAD",IF(AJ8>='⚙ Parámetros'!B25,"PRIORIDAD MEDIA",IF(AJ8>='⚙ Parámetros'!B26,"BAJA PRIORIDAD","DESCARTAR"))))) -> PRIORIDAD MEDIA | AL8: =IF(AB8>=8,"SÍ ⚑","—") -> SÍ ⚑ | AM8: 100 | AN8: =IF(AM8="","—",IF(AM8<'⚙ Parámetros'!B29,"🟢 Corto",IF(AM8<'⚙ Parámetros'!B30,"🟡 Medio","🔴 Largo"))) -> 🔴 Largo
A9: 5 | B9: MPG-COM-014 Integracion DocuWare - D365 | C9: Supply chain y logística | D9: Marc Bometon | E9: 30/06/2025 | F9: 8 | G9: 1 | H9: 5 | I9: 8 | J9: 7 | K9: 1 | L9: 8 | M9: 3 | N9: 7 | O9: 1 | P9: 7 | Q9: 8 | R9: 5 | S9: 5 | T9: 5 | U9: 5 | V9: 5 | W9: 6 | X9: 3 | Y9: 4 | Z9: 2 | AA9: 8 | AB9: =IFERROR((30/100*MAX('⚙ Parámetros'!D15/(1+2^(-'⚙ Parámetros'!C15*(F9-'⚙ Parámetros'!B15))),'⚙ Parámetros'!G15/(1+2^(-'⚙ Parámetros'!F15*(F9-'⚙ Parámetros'!E15))),1)*F9+30/100*MAX('⚙ Parámetros'!D15/(1+2^(-'⚙ Parámetros'!C15*(G9-'⚙ Parámetros'!B15))),'⚙ Parámetros'!G15/(1+2^(-'⚙ Parámetros'!F15*(G9-'⚙ Parámetros'!E15))),1)*G9+20/100*MAX('⚙ Parámetros'!D15/(1+2^(-'⚙ Parámetros'!C15*(H9-'⚙ Parámetros'!B15))),'⚙ Parámetros'!G15/(1+2^(-'⚙ Parámetros'!F15*(H9-'⚙ Parámetros'!E15))),1)*H9+20/100*MAX('⚙ Parámetros'!D15/(1+2^(-'⚙ Parámetros'!C15*(I9-'⚙ Parámetros'!B15))),'⚙ Parámetros'!G15/(1+2^(-'⚙ Parámetros'!F15*(I9-'⚙ Parámetros'!E15))),1)*I9)/(30/100*MAX('⚙ Parámetros'!D15/(1+2^(-'⚙ Parámetros'!C15*(F9-'⚙ Parámetros'!B15))),'⚙ Parámetros'!G15/(1+2^(-'⚙ Parámetros'!F15*(F9-'⚙ Parámetros'!E15))),1)+30/100*MAX('⚙ Parámetros'!D15/(1+2^(-'⚙ Parámetros'!C15*(G9-'⚙ Parámetros'!B15))),'⚙ Parámetros'!G15/(1+2^(-'⚙ Parámetros'!F15*(G9-'⚙ Parámetros'!E15))),1)+20/100*MAX('⚙ Parámetros'!D15/(1+2^(-'⚙ Parámetros'!C15*(H9-'⚙ Parámetros'!B15))),'⚙ Parámetros'!G15/(1+2^(-'⚙ Parámetros'!F15*(H9-'⚙ Parámetros'!E15))),1)+20/100*MAX('⚙ Parámetros'!D15/(1+2^(-'⚙ Parámetros'!C15*(I9-'⚙ Parámetros'!B15))),'⚙ Parámetros'!G15/(1+2^(-'⚙ Parámetros'!F15*(I9-'⚙ Parámetros'!E15))),1)),0) -> 7.2748815 | AC9: =IFERROR((35/100*MAX('⚙ Parámetros'!D16/(1+2^(-'⚙ Parámetros'!C16*(J9-'⚙ Parámetros'!B16))),'⚙ Parámetros'!G16/(1+2^(-'⚙ Parámetros'!F16*(J9-'⚙ Parámetros'!E16))),1)*J9+25/100*MAX('⚙ Parámetros'!D16/(1+2^(-'⚙ Parámetros'!C16*(K9-'⚙ Parámetros'!B16))),'⚙ Parámetros'!G16/(1+2^(-'⚙ Parámetros'!F16*(K9-'⚙ Parámetros'!E16))),1)*K9+20/100*MAX('⚙ Parámetros'!D16/(1+2^(-'⚙ Parámetros'!C16*(L9-'⚙ Parámetros'!B16))),'⚙ Parámetros'!G16/(1+2^(-'⚙ Parámetros'!F16*(L9-'⚙ Parámetros'!E16))),1)*L9+20/100*MAX('⚙ Parámetros'!D16/(1+2^(-'⚙ Parámetros'!C16*(M9-'⚙ Parámetros'!B16))),'⚙ Parámetros'!G16/(1+2^(-'⚙ Parámetros'!F16*(M9-'⚙ Parámetros'!E16))),1)*M9)/(35/100*MAX('⚙ Parámetros'!D16/(1+2^(-'⚙ Parámetros'!C16*(J9-'⚙ Parámetros'!B16))),'⚙ Parámetros'!G16/(1+2^(-'⚙ Parámetros'!F16*(J9-'⚙ Parámetros'!E16))),1)+25/100*MAX('⚙ Parámetros'!D16/(1+2^(-'⚙ Parámetros'!C16*(K9-'⚙ Parámetros'!B16))),'⚙ Parámetros'!G16/(1+2^(-'⚙ Parámetros'!F16*(K9-'⚙ Parámetros'!E16))),1)+20/100*MAX('⚙ Parámetros'!D16/(1+2^(-'⚙ Parámetros'!C16*(L9-'⚙ Parámetros'!B16))),'⚙ Parámetros'!G16/(1+2^(-'⚙ Parámetros'!F16*(L9-'⚙ Parámetros'!E16))),1)+20/100*MAX('⚙ Parámetros'!D16/(1+2^(-'⚙ Parámetros'!C16*(M9-'⚙ Parámetros'!B16))),'⚙ Parámetros'!G16/(1+2^(-'⚙ Parámetros'!F16*(M9-'⚙ Parámetros'!E16))),1)),0) -> 6.3868613 | AD9: =IFERROR((30/100*MAX('⚙ Parámetros'!D17/(1+2^(-'⚙ Parámetros'!C17*(N9-'⚙ Parámetros'!B17))),'⚙ Parámetros'!G17/(1+2^(-'⚙ Parámetros'!F17*(N9-'⚙ Parámetros'!E17))),1)*N9+25/100*MAX('⚙ Parámetros'!D17/(1+2^(-'⚙ Parámetros'!C17*(O9-'⚙ Parámetros'!B17))),'⚙ Parámetros'!G17/(1+2^(-'⚙ Parámetros'!F17*(O9-'⚙ Parámetros'!E17))),1)*O9+25/100*MAX('⚙ Parámetros'!D17/(1+2^(-'⚙ Parámetros'!C17*(P9-'⚙ Parámetros'!B17))),'⚙ Parámetros'!G17/(1+2^(-'⚙ Parámetros'!F17*(P9-'⚙ Parámetros'!E17))),1)*P9+20/100*MAX('⚙ Parámetros'!D17/(1+2^(-'⚙ Parámetros'!C17*(Q9-'⚙ Parámetros'!B17))),'⚙ Parámetros'!G17/(1+2^(-'⚙ Parámetros'!F17*(Q9-'⚙ Parámetros'!E17))),1)*Q9)/(30/100*MAX('⚙ Parámetros'!D17/(1+2^(-'⚙ Parámetros'!C17*(N9-'⚙ Parámetros'!B17))),'⚙ Parámetros'!G17/(1+2^(-'⚙ Parámetros'!F17*(N9-'⚙ Parámetros'!E17))),1)+25/100*MAX('⚙ Parámetros'!D17/(1+2^(-'⚙ Parámetros'!C17*(O9-'⚙ Parámetros'!B17))),'⚙ Parámetros'!G17/(1+2^(-'⚙ Parámetros'!F17*(O9-'⚙ Parámetros'!E17))),1)+25/100*MAX('⚙ Parámetros'!D17/(1+2^(-'⚙ Parámetros'!C17*(P9-'⚙ Parámetros'!B17))),'⚙ Parámetros'!G17/(1+2^(-'⚙ Parámetros'!F17*(P9-'⚙ Parámetros'!E17))),1)+20/100*MAX('⚙ Parámetros'!D17/(1+2^(-'⚙ Parámetros'!C17*(Q9-'⚙ Parámetros'!B17))),'⚙ Parámetros'!G17/(1+2^(-'⚙ Parámetros'!F17*(Q9-'⚙ Parámetros'!E17))),1)),0) -> 6.7218543 | AE9: =IFERROR((30/100*MAX('⚙ Parámetros'!D18/(1+2^(-'⚙ Parámetros'!C18*(R9-'⚙ Parámetros'!B18))),'⚙ Parámetros'!G18/(1+2^(-'⚙ Parámetros'!F18*(R9-'⚙ Parámetros'!E18))),1)*R9+30/100*MAX('⚙ Parámetros'!D18/(1+2^(-'⚙ Parámetros'!C18*(S9-'⚙ Parámetros'!B18))),'⚙ Parámetros'!G18/(1+2^(-'⚙ Parámetros'!F18*(S9-'⚙ Parámetros'!E18))),1)*S9+20/100*MAX('⚙ Parámetros'!D18/(1+2^(-'⚙ Parámetros'!C18*(T9-'⚙ Parámetros'!B18))),'⚙ Parámetros'!G18/(1+2^(-'⚙ Parámetros'!F18*(T9-'⚙ Parámetros'!E18))),1)*T9+20/100*MAX('⚙ Parámetros'!D18/(1+2^(-'⚙ Parámetros'!C18*(U9-'⚙ Parámetros'!B18))),'⚙ Parámetros'!G18/(1+2^(-'⚙ Parámetros'!F18*(U9-'⚙ Parámetros'!E18))),1)*U9)/(30/100*MAX('⚙ Parámetros'!D18/(1+2^(-'⚙ Parámetros'!C18*(R9-'⚙ Parámetros'!B18))),'⚙ Parámetros'!G18/(1+2^(-'⚙ Parámetros'!F18*(R9-'⚙ Parámetros'!E18))),1)+30/100*MAX('⚙ Parámetros'!D18/(1+2^(-'⚙ Parámetros'!C18*(S9-'⚙ Parámetros'!B18))),'⚙ Parámetros'!G18/(1+2^(-'⚙ Parámetros'!F18*(S9-'⚙ Parámetros'!E18))),1)+20/100*MAX('⚙ Parámetros'!D18/(1+2^(-'⚙ Parámetros'!C18*(T9-'⚙ Parámetros'!B18))),'⚙ Parámetros'!G18/(1+2^(-'⚙ Parámetros'!F18*(T9-'⚙ Parámetros'!E18))),1)+20/100*MAX('⚙ Parámetros'!D18/(1+2^(-'⚙ Parámetros'!C18*(U9-'⚙ Parámetros'!B18))),'⚙ Parámetros'!G18/(1+2^(-'⚙ Parámetros'!F18*(U9-'⚙ Parámetros'!E18))),1)),0) -> 5 | AF9: =IFERROR((30/100*MAX('⚙ Parámetros'!D19/(1+2^(-'⚙ Parámetros'!C19*(V9-'⚙ Parámetros'!B19))),'⚙ Parámetros'!G19/(1+2^(-'⚙ Parámetros'!F19*(V9-'⚙ Parámetros'!E19))),1)*V9+35/100*MAX('⚙ Parámetros'!D19/(1+2^(-'⚙ Parámetros'!C19*(W9-'⚙ Parámetros'!B19))),'⚙ Parámetros'!G19/(1+2^(-'⚙ Parámetros'!F19*(W9-'⚙ Parámetros'!E19))),1)*W9+35/100*MAX('⚙ Parámetros'!D19/(1+2^(-'⚙ Parámetros'!C19*(X9-'⚙ Parámetros'!B19))),'⚙ Parámetros'!G19/(1+2^(-'⚙ Parámetros'!F19*(X9-'⚙ Parámetros'!E19))),1)*X9)/(30/100*MAX('⚙ Parámetros'!D19/(1+2^(-'⚙ Parámetros'!C19*(V9-'⚙ Parámetros'!B19))),'⚙ Parámetros'!G19/(1+2^(-'⚙ Parámetros'!F19*(V9-'⚙ Parámetros'!E19))),1)+35/100*MAX('⚙ Parámetros'!D19/(1+2^(-'⚙ Parámetros'!C19*(W9-'⚙ Parámetros'!B19))),'⚙ Parámetros'!G19/(1+2^(-'⚙ Parámetros'!F19*(W9-'⚙ Parámetros'!E19))),1)+35/100*MAX('⚙ Parámetros'!D19/(1+2^(-'⚙ Parámetros'!C19*(X9-'⚙ Parámetros'!B19))),'⚙ Parámetros'!G19/(1+2^(-'⚙ Parámetros'!F19*(X9-'⚙ Parámetros'!E19))),1)),0) -> 5.0782123 | AG9: =IFERROR((35/100*MAX('⚙ Parámetros'!D20/(1+2^(-'⚙ Parámetros'!C20*(Y9-'⚙ Parámetros'!B20))),'⚙ Parámetros'!G20/(1+2^(-'⚙ Parámetros'!F20*(Y9-'⚙ Parámetros'!E20))),1)*Y9+35/100*MAX('⚙ Parámetros'!D20/(1+2^(-'⚙ Parámetros'!C20*(Z9-'⚙ Parámetros'!B20))),'⚙ Parámetros'!G20/(1+2^(-'⚙ Parámetros'!F20*(Z9-'⚙ Parámetros'!E20))),1)*Z9+30/100*MAX('⚙ Parámetros'!D20/(1+2^(-'⚙ Parámetros'!C20*(AA9-'⚙ Parámetros'!B20))),'⚙ Parámetros'!G20/(1+2^(-'⚙ Parámetros'!F20*(AA9-'⚙ Parámetros'!E20))),1)*AA9)/(35/100*MAX('⚙ Parámetros'!D20/(1+2^(-'⚙ Parámetros'!C20*(Y9-'⚙ Parámetros'!B20))),'⚙ Parámetros'!G20/(1+2^(-'⚙ Parámetros'!F20*(Y9-'⚙ Parámetros'!E20))),1)+35/100*MAX('⚙ Parámetros'!D20/(1+2^(-'⚙ Parámetros'!C20*(Z9-'⚙ Parámetros'!B20))),'⚙ Parámetros'!G20/(1+2^(-'⚙ Parámetros'!F20*(Z9-'⚙ Parámetros'!E20))),1)+30/100*MAX('⚙ Parámetros'!D20/(1+2^(-'⚙ Parámetros'!C20*(AA9-'⚙ Parámetros'!B20))),'⚙ Parámetros'!G20/(1+2^(-'⚙ Parámetros'!F20*(AA9-'⚙ Parámetros'!E20))),1)),0) -> 5.8125 | AH9: =('⚙ Parámetros'!B5/100*AB9+'⚙ Parámetros'!B6/100*AC9+'⚙ Parámetros'!B7/100*AD9+'⚙ Parámetros'!B8/100*AE9+'⚙ Parámetros'!B9/100*AF9+'⚙ Parámetros'!B10/100*AG9) -> 6.3770288 | AI9: =MIN(1+MAX(0,TODAY()-DATE(2025,6,30))/365*'⚙ Parámetros'!B33,'⚙ Parámetros'!B34) -> 1.1426027 | AJ9: =IFERROR(MIN(AH9*AI9,10),0) -> 7.2864106 | AK9: =IF(AB9>='⚙ Parámetros'!B23,"⚑ AUTO-PRIOR.(D1≥8)",IF(AJ9>='⚙ Parámetros'!B23,"PRIORITARIO",IF(AJ9>='⚙ Parámetros'!B24,"ALTA PRIORIDAD",IF(AJ9>='⚙ Parámetros'!B25,"PRIORIDAD MEDIA",IF(AJ9>='⚙ Parámetros'!B26,"BAJA PRIORIDAD","DESCARTAR"))))) -> ALTA PRIORIDAD | AL9: =IF(AB9>=8,"SÍ ⚑","—") -> — | AM9: 25 | AN9: =IF(AM9="","—",IF(AM9<'⚙ Parámetros'!B29,"🟢 Corto",IF(AM9<'⚙ Parámetros'!B30,"🟡 Medio","🔴 Largo"))) -> 🟢 Corto
A10: 6 | B10: MPG-VTA-006_1 Integracion B2B --> MiddleWare | C10: Ventas y marketing | D10: Marc Bometon | E10: 24/03/2026 | F10: 5 | G10: 1 | H10: 5 | I10: 1 | J10: 10 | K10: 9 | L10: 8 | M10: 9 | N10: 8 | O10: 8 | P10: 7 | Q10: 6 | R10: 9 | S10: 9 | T10: 5 | U10: 5 | V10: 7 | W10: 6 | X10: 5 | Y10: 5 | Z10: 2 | AA10: 5 | AB10: =IFERROR((30/100*MAX('⚙ Parámetros'!D15/(1+2^(-'⚙ Parámetros'!C15*(F10-'⚙ Parámetros'!B15))),'⚙ Parámetros'!G15/(1+2^(-'⚙ Parámetros'!F15*(F10-'⚙ Parámetros'!E15))),1)*F10+30/100*MAX('⚙ Parámetros'!D15/(1+2^(-'⚙ Parámetros'!C15*(G10-'⚙ Parámetros'!B15))),'⚙ Parámetros'!G15/(1+2^(-'⚙ Parámetros'!F15*(G10-'⚙ Parámetros'!E15))),1)*G10+20/100*MAX('⚙ Parámetros'!D15/(1+2^(-'⚙ Parámetros'!C15*(H10-'⚙ Parámetros'!B15))),'⚙ Parámetros'!G15/(1+2^(-'⚙ Parámetros'!F15*(H10-'⚙ Parámetros'!E15))),1)*H10+20/100*MAX('⚙ Parámetros'!D15/(1+2^(-'⚙ Parámetros'!C15*(I10-'⚙ Parámetros'!B15))),'⚙ Parámetros'!G15/(1+2^(-'⚙ Parámetros'!F15*(I10-'⚙ Parámetros'!E15))),1)*I10)/(30/100*MAX('⚙ Parámetros'!D15/(1+2^(-'⚙ Parámetros'!C15*(F10-'⚙ Parámetros'!B15))),'⚙ Parámetros'!G15/(1+2^(-'⚙ Parámetros'!F15*(F10-'⚙ Parámetros'!E15))),1)+30/100*MAX('⚙ Parámetros'!D15/(1+2^(-'⚙ Parámetros'!C15*(G10-'⚙ Parámetros'!B15))),'⚙ Parámetros'!G15/(1+2^(-'⚙ Parámetros'!F15*(G10-'⚙ Parámetros'!E15))),1)+20/100*MAX('⚙ Parámetros'!D15/(1+2^(-'⚙ Parámetros'!C15*(H10-'⚙ Parámetros'!B15))),'⚙ Parámetros'!G15/(1+2^(-'⚙ Parámetros'!F15*(H10-'⚙ Parámetros'!E15))),1)+20/100*MAX('⚙ Parámetros'!D15/(1+2^(-'⚙ Parámetros'!C15*(I10-'⚙ Parámetros'!B15))),'⚙ Parámetros'!G15/(1+2^(-'⚙ Parámetros'!F15*(I10-'⚙ Parámetros'!E15))),1)),0) -> 3.4615385 | AC10: =IFERROR((35/100*MAX('⚙ Parámetros'!D16/(1+2^(-'⚙ Parámetros'!C16*(J10-'⚙ Parámetros'!B16))),'⚙ Parámetros'!G16/(1+2^(-'⚙ Parámetros'!F16*(J10-'⚙ Parámetros'!E16))),1)*J10+25/100*MAX('⚙ Parámetros'!D16/(1+2^(-'⚙ Parámetros'!C16*(K10-'⚙ Parámetros'!B16))),'⚙ Parámetros'!G16/(1+2^(-'⚙ Parámetros'!F16*(K10-'⚙ Parámetros'!E16))),1)*K10+20/100*MAX('⚙ Parámetros'!D16/(1+2^(-'⚙ Parámetros'!C16*(L10-'⚙ Parámetros'!B16))),'⚙ Parámetros'!G16/(1+2^(-'⚙ Parámetros'!F16*(L10-'⚙ Parámetros'!E16))),1)*L10+20/100*MAX('⚙ Parámetros'!D16/(1+2^(-'⚙ Parámetros'!C16*(M10-'⚙ Parámetros'!B16))),'⚙ Parámetros'!G16/(1+2^(-'⚙ Parámetros'!F16*(M10-'⚙ Parámetros'!E16))),1)*M10)/(35/100*MAX('⚙ Parámetros'!D16/(1+2^(-'⚙ Parámetros'!C16*(J10-'⚙ Parámetros'!B16))),'⚙ Parámetros'!G16/(1+2^(-'⚙ Parámetros'!F16*(J10-'⚙ Parámetros'!E16))),1)+25/100*MAX('⚙ Parámetros'!D16/(1+2^(-'⚙ Parámetros'!C16*(K10-'⚙ Parámetros'!B16))),'⚙ Parámetros'!G16/(1+2^(-'⚙ Parámetros'!F16*(K10-'⚙ Parámetros'!E16))),1)+20/100*MAX('⚙ Parámetros'!D16/(1+2^(-'⚙ Parámetros'!C16*(L10-'⚙ Parámetros'!B16))),'⚙ Parámetros'!G16/(1+2^(-'⚙ Parámetros'!F16*(L10-'⚙ Parámetros'!E16))),1)+20/100*MAX('⚙ Parámetros'!D16/(1+2^(-'⚙ Parámetros'!C16*(M10-'⚙ Parámetros'!B16))),'⚙ Parámetros'!G16/(1+2^(-'⚙ Parámetros'!F16*(M10-'⚙ Parámetros'!E16))),1)),0) -> 9.290611 | AD10: =IFERROR((30/100*MAX('⚙ Parámetros'!D17/(1+2^(-'⚙ Parámetros'!C17*(N10-'⚙ Parámetros'!B17))),'⚙ Parámetros'!G17/(1+2^(-'⚙ Parámetros'!F17*(N10-'⚙ Parámetros'!E17))),1)*N10+25/100*MAX('⚙ Parámetros'!D17/(1+2^(-'⚙ Parámetros'!C17*(O10-'⚙ Parámetros'!B17))),'⚙ Parámetros'!G17/(1+2^(-'⚙ Parámetros'!F17*(O10-'⚙ Parámetros'!E17))),1)*O10+25/100*MAX('⚙ Parámetros'!D17/(1+2^(-'⚙ Parámetros'!C17*(P10-'⚙ Parámetros'!B17))),'⚙ Parámetros'!G17/(1+2^(-'⚙ Parámetros'!F17*(P10-'⚙ Parámetros'!E17))),1)*P10+20/100*MAX('⚙ Parámetros'!D17/(1+2^(-'⚙ Parámetros'!C17*(Q10-'⚙ Parámetros'!B17))),'⚙ Parámetros'!G17/(1+2^(-'⚙ Parámetros'!F17*(Q10-'⚙ Parámetros'!E17))),1)*Q10)/(30/100*MAX('⚙ Parámetros'!D17/(1+2^(-'⚙ Parámetros'!C17*(N10-'⚙ Parámetros'!B17))),'⚙ Parámetros'!G17/(1+2^(-'⚙ Parámetros'!F17*(N10-'⚙ Parámetros'!E17))),1)+25/100*MAX('⚙ Parámetros'!D17/(1+2^(-'⚙ Parámetros'!C17*(O10-'⚙ Parámetros'!B17))),'⚙ Parámetros'!G17/(1+2^(-'⚙ Parámetros'!F17*(O10-'⚙ Parámetros'!E17))),1)+25/100*MAX('⚙ Parámetros'!D17/(1+2^(-'⚙ Parámetros'!C17*(P10-'⚙ Parámetros'!B17))),'⚙ Parámetros'!G17/(1+2^(-'⚙ Parámetros'!F17*(P10-'⚙ Parámetros'!E17))),1)+20/100*MAX('⚙ Parámetros'!D17/(1+2^(-'⚙ Parámetros'!C17*(Q10-'⚙ Parámetros'!B17))),'⚙ Parámetros'!G17/(1+2^(-'⚙ Parámetros'!F17*(Q10-'⚙ Parámetros'!E17))),1)),0) -> 7.5139442 | AE10: =IFERROR((30/100*MAX('⚙ Parámetros'!D18/(1+2^(-'⚙ Parámetros'!C18*(R10-'⚙ Parámetros'!B18))),'⚙ Parámetros'!G18/(1+2^(-'⚙ Parámetros'!F18*(R10-'⚙ Parámetros'!E18))),1)*R10+30/100*MAX('⚙ Parámetros'!D18/(1+2^(-'⚙ Parámetros'!C18*(S10-'⚙ Parámetros'!B18))),'⚙ Parámetros'!G18/(1+2^(-'⚙ Parámetros'!F18*(S10-'⚙ Parámetros'!E18))),1)*S10+20/100*MAX('⚙ Parámetros'!D18/(1+2^(-'⚙ Parámetros'!C18*(T10-'⚙ Parámetros'!B18))),'⚙ Parámetros'!G18/(1+2^(-'⚙ Parámetros'!F18*(T10-'⚙ Parámetros'!E18))),1)*T10+20/100*MAX('⚙ Parámetros'!D18/(1+2^(-'⚙ Parámetros'!C18*(U10-'⚙ Parámetros'!B18))),'⚙ Parámetros'!G18/(1+2^(-'⚙ Parámetros'!F18*(U10-'⚙ Parámetros'!E18))),1)*U10)/(30/100*MAX('⚙ Parámetros'!D18/(1+2^(-'⚙ Parámetros'!C18*(R10-'⚙ Parámetros'!B18))),'⚙ Parámetros'!G18/(1+2^(-'⚙ Parámetros'!F18*(R10-'⚙ Parámetros'!E18))),1)+30/100*MAX('⚙ Parámetros'!D18/(1+2^(-'⚙ Parámetros'!C18*(S10-'⚙ Parámetros'!B18))),'⚙ Parámetros'!G18/(1+2^(-'⚙ Parámetros'!F18*(S10-'⚙ Parámetros'!E18))),1)+20/100*MAX('⚙ Parámetros'!D18/(1+2^(-'⚙ Parámetros'!C18*(T10-'⚙ Parámetros'!B18))),'⚙ Parámetros'!G18/(1+2^(-'⚙ Parámetros'!F18*(T10-'⚙ Parámetros'!E18))),1)+20/100*MAX('⚙ Parámetros'!D18/(1+2^(-'⚙ Parámetros'!C18*(U10-'⚙ Parámetros'!B18))),'⚙ Parámetros'!G18/(1+2^(-'⚙ Parámetros'!F18*(U10-'⚙ Parámetros'!E18))),1)),0) -> 8.180106 | AF10: =IFERROR((30/100*MAX('⚙ Parámetros'!D19/(1+2^(-'⚙ Parámetros'!C19*(V10-'⚙ Parámetros'!B19))),'⚙ Parámetros'!G19/(1+2^(-'⚙ Parámetros'!F19*(V10-'⚙ Parámetros'!E19))),1)*V10+35/100*MAX('⚙ Parámetros'!D19/(1+2^(-'⚙ Parámetros'!C19*(W10-'⚙ Parámetros'!B19))),'⚙ Parámetros'!G19/(1+2^(-'⚙ Parámetros'!F19*(W10-'⚙ Parámetros'!E19))),1)*W10+35/100*MAX('⚙ Parámetros'!D19/(1+2^(-'⚙ Parámetros'!C19*(X10-'⚙ Parámetros'!B19))),'⚙ Parámetros'!G19/(1+2^(-'⚙ Parámetros'!F19*(X10-'⚙ Parámetros'!E19))),1)*X10)/(30/100*MAX('⚙ Parámetros'!D19/(1+2^(-'⚙ Parámetros'!C19*(V10-'⚙ Parámetros'!B19))),'⚙ Parámetros'!G19/(1+2^(-'⚙ Parámetros'!F19*(V10-'⚙ Parámetros'!E19))),1)+35/100*MAX('⚙ Parámetros'!D19/(1+2^(-'⚙ Parámetros'!C19*(W10-'⚙ Parámetros'!B19))),'⚙ Parámetros'!G19/(1+2^(-'⚙ Parámetros'!F19*(W10-'⚙ Parámetros'!E19))),1)+35/100*MAX('⚙ Parámetros'!D19/(1+2^(-'⚙ Parámetros'!C19*(X10-'⚙ Parámetros'!B19))),'⚙ Parámetros'!G19/(1+2^(-'⚙ Parámetros'!F19*(X10-'⚙ Parámetros'!E19))),1)),0) -> 6.042735 | AG10: =IFERROR((35/100*MAX('⚙ Parámetros'!D20/(1+2^(-'⚙ Parámetros'!C20*(Y10-'⚙ Parámetros'!B20))),'⚙ Parámetros'!G20/(1+2^(-'⚙ Parámetros'!F20*(Y10-'⚙ Parámetros'!E20))),1)*Y10+35/100*MAX('⚙ Parámetros'!D20/(1+2^(-'⚙ Parámetros'!C20*(Z10-'⚙ Parámetros'!B20))),'⚙ Parámetros'!G20/(1+2^(-'⚙ Parámetros'!F20*(Z10-'⚙ Parámetros'!E20))),1)*Z10+30/100*MAX('⚙ Parámetros'!D20/(1+2^(-'⚙ Parámetros'!C20*(AA10-'⚙ Parámetros'!B20))),'⚙ Parámetros'!G20/(1+2^(-'⚙ Parámetros'!F20*(AA10-'⚙ Parámetros'!E20))),1)*AA10)/(35/100*MAX('⚙ Parámetros'!D20/(1+2^(-'⚙ Parámetros'!C20*(Y10-'⚙ Parámetros'!B20))),'⚙ Parámetros'!G20/(1+2^(-'⚙ Parámetros'!F20*(Y10-'⚙ Parámetros'!E20))),1)+35/100*MAX('⚙ Parámetros'!D20/(1+2^(-'⚙ Parámetros'!C20*(Z10-'⚙ Parámetros'!B20))),'⚙ Parámetros'!G20/(1+2^(-'⚙ Parámetros'!F20*(Z10-'⚙ Parámetros'!E20))),1)+30/100*MAX('⚙ Parámetros'!D20/(1+2^(-'⚙ Parámetros'!C20*(AA10-'⚙ Parámetros'!B20))),'⚙ Parámetros'!G20/(1+2^(-'⚙ Parámetros'!F20*(AA10-'⚙ Parámetros'!E20))),1)),0) -> 4.1369863 | AH10: =('⚙ Parámetros'!B5/100*AB10+'⚙ Parámetros'!B6/100*AC10+'⚙ Parámetros'!B7/100*AD10+'⚙ Parámetros'!B8/100*AE10+'⚙ Parámetros'!B9/100*AF10+'⚙ Parámetros'!B10/100*AG10) -> 6.3162177 | AI10: =MIN(1+MAX(0,TODAY()-DATE(2026,3,24))/365*'⚙ Parámetros'!B33,'⚙ Parámetros'!B34) -> 1.0328767 | AJ10: =IFERROR(MIN(AH10*AI10,10),0) -> 6.5238742 | AK10: =IF(AB10>='⚙ Parámetros'!B23,"⚑ AUTO-PRIOR.(D1≥8)",IF(AJ10>='⚙ Parámetros'!B23,"PRIORITARIO",IF(AJ10>='⚙ Parámetros'!B24,"ALTA PRIORIDAD",IF(AJ10>='⚙ Parámetros'!B25,"PRIORIDAD MEDIA",IF(AJ10>='⚙ Parámetros'!B26,"BAJA PRIORIDAD","DESCARTAR"))))) -> PRIORIDAD MEDIA | AL10: =IF(AB10>=8,"SÍ ⚑","—") -> — | AM10: 34 | AN10: =IF(AM10="","—",IF(AM10<'⚙ Parámetros'!B29,"🟢 Corto",IF(AM10<'⚙ Parámetros'!B30,"🟡 Medio","🔴 Largo"))) -> 🟡 Medio
A11: 7 | B11: MPG-CAL-025 Mejoras de calidad - alerta PDA | C11: Regulatorio y calidad | D11: Marc Bometon | E11: 25/11/2025 | F11: 8 | G11: 7 | H11: 1 | I11: 8 | J11: 1 | K11: 1 | L11: 8 | M11: 3 | N11: 1 | O11: 6 | P11: 1 | Q11: 8 | R11: 9 | S11: 9 | T11: 5 | U11: 5 | V11: 8 | W11: 4 | X11: 5 | Y11: 4 | Z11: 2 | AA11: 5 | AB11: =IFERROR((30/100*MAX('⚙ Parámetros'!D15/(1+2^(-'⚙ Parámetros'!C15*(F11-'⚙ Parámetros'!B15))),'⚙ Parámetros'!G15/(1+2^(-'⚙ Parámetros'!F15*(F11-'⚙ Parámetros'!E15))),1)*F11+30/100*MAX('⚙ Parámetros'!D15/(1+2^(-'⚙ Parámetros'!C15*(G11-'⚙ Parámetros'!B15))),'⚙ Parámetros'!G15/(1+2^(-'⚙ Parámetros'!F15*(G11-'⚙ Parámetros'!E15))),1)*G11+20/100*MAX('⚙ Parámetros'!D15/(1+2^(-'⚙ Parámetros'!C15*(H11-'⚙ Parámetros'!B15))),'⚙ Parámetros'!G15/(1+2^(-'⚙ Parámetros'!F15*(H11-'⚙ Parámetros'!E15))),1)*H11+20/100*MAX('⚙ Parámetros'!D15/(1+2^(-'⚙ Parámetros'!C15*(I11-'⚙ Parámetros'!B15))),'⚙ Parámetros'!G15/(1+2^(-'⚙ Parámetros'!F15*(I11-'⚙ Parámetros'!E15))),1)*I11)/(30/100*MAX('⚙ Parámetros'!D15/(1+2^(-'⚙ Parámetros'!C15*(F11-'⚙ Parámetros'!B15))),'⚙ Parámetros'!G15/(1+2^(-'⚙ Parámetros'!F15*(F11-'⚙ Parámetros'!E15))),1)+30/100*MAX('⚙ Parámetros'!D15/(1+2^(-'⚙ Parámetros'!C15*(G11-'⚙ Parámetros'!B15))),'⚙ Parámetros'!G15/(1+2^(-'⚙ Parámetros'!F15*(G11-'⚙ Parámetros'!E15))),1)+20/100*MAX('⚙ Parámetros'!D15/(1+2^(-'⚙ Parámetros'!C15*(H11-'⚙ Parámetros'!B15))),'⚙ Parámetros'!G15/(1+2^(-'⚙ Parámetros'!F15*(H11-'⚙ Parámetros'!E15))),1)+20/100*MAX('⚙ Parámetros'!D15/(1+2^(-'⚙ Parámetros'!C15*(I11-'⚙ Parámetros'!B15))),'⚙ Parámetros'!G15/(1+2^(-'⚙ Parámetros'!F15*(I11-'⚙ Parámetros'!E15))),1)),0) -> 7.4660194 | AC11: =IFERROR((35/100*MAX('⚙ Parámetros'!D16/(1+2^(-'⚙ Parámetros'!C16*(J11-'⚙ Parámetros'!B16))),'⚙ Parámetros'!G16/(1+2^(-'⚙ Parámetros'!F16*(J11-'⚙ Parámetros'!E16))),1)*J11+25/100*MAX('⚙ Parámetros'!D16/(1+2^(-'⚙ Parámetros'!C16*(K11-'⚙ Parámetros'!B16))),'⚙ Parámetros'!G16/(1+2^(-'⚙ Parámetros'!F16*(K11-'⚙ Parámetros'!E16))),1)*K11+20/100*MAX('⚙ Parámetros'!D16/(1+2^(-'⚙ Parámetros'!C16*(L11-'⚙ Parámetros'!B16))),'⚙ Parámetros'!G16/(1+2^(-'⚙ Parámetros'!F16*(L11-'⚙ Parámetros'!E16))),1)*L11+20/100*MAX('⚙ Parámetros'!D16/(1+2^(-'⚙ Parámetros'!C16*(M11-'⚙ Parámetros'!B16))),'⚙ Parámetros'!G16/(1+2^(-'⚙ Parámetros'!F16*(M11-'⚙ Parámetros'!E16))),1)*M11)/(35/100*MAX('⚙ Parámetros'!D16/(1+2^(-'⚙ Parámetros'!C16*(J11-'⚙ Parámetros'!B16))),'⚙ Parámetros'!G16/(1+2^(-'⚙ Parámetros'!F16*(J11-'⚙ Parámetros'!E16))),1)+25/100*MAX('⚙ Parámetros'!D16/(1+2^(-'⚙ Parámetros'!C16*(K11-'⚙ Parámetros'!B16))),'⚙ Parámetros'!G16/(1+2^(-'⚙ Parámetros'!F16*(K11-'⚙ Parámetros'!E16))),1)+20/100*MAX('⚙ Parámetros'!D16/(1+2^(-'⚙ Parámetros'!C16*(L11-'⚙ Parámetros'!B16))),'⚙ Parámetros'!G16/(1+2^(-'⚙ Parámetros'!F16*(L11-'⚙ Parámetros'!E16))),1)+20/100*MAX('⚙ Parámetros'!D16/(1+2^(-'⚙ Parámetros'!C16*(M11-'⚙ Parámetros'!B16))),'⚙ Parámetros'!G16/(1+2^(-'⚙ Parámetros'!F16*(M11-'⚙ Parámetros'!E16))),1)),0) -> 4.9411765 | AD11: =IFERROR((30/100*MAX('⚙ Parámetros'!D17/(1+2^(-'⚙ Parámetros'!C17*(N11-'⚙ Parámetros'!B17))),'⚙ Parámetros'!G17/(1+2^(-'⚙ Parámetros'!F17*(N11-'⚙ Parámetros'!E17))),1)*N11+25/100*MAX('⚙ Parámetros'!D17/(1+2^(-'⚙ Parámetros'!C17*(O11-'⚙ Parámetros'!B17))),'⚙ Parámetros'!G17/(1+2^(-'⚙ Parámetros'!F17*(O11-'⚙ Parámetros'!E17))),1)*O11+25/100*MAX('⚙ Parámetros'!D17/(1+2^(-'⚙ Parámetros'!C17*(P11-'⚙ Parámetros'!B17))),'⚙ Parámetros'!G17/(1+2^(-'⚙ Parámetros'!F17*(P11-'⚙ Parámetros'!E17))),1)*P11+20/100*MAX('⚙ Parámetros'!D17/(1+2^(-'⚙ Parámetros'!C17*(Q11-'⚙ Parámetros'!B17))),'⚙ Parámetros'!G17/(1+2^(-'⚙ Parámetros'!F17*(Q11-'⚙ Parámetros'!E17))),1)*Q11)/(30/100*MAX('⚙ Parámetros'!D17/(1+2^(-'⚙ Parámetros'!C17*(N11-'⚙ Parámetros'!B17))),'⚙ Parámetros'!G17/(1+2^(-'⚙ Parámetros'!F17*(N11-'⚙ Parámetros'!E17))),1)+25/100*MAX('⚙ Parámetros'!D17/(1+2^(-'⚙ Parámetros'!C17*(O11-'⚙ Parámetros'!B17))),'⚙ Parámetros'!G17/(1+2^(-'⚙ Parámetros'!F17*(O11-'⚙ Parámetros'!E17))),1)+25/100*MAX('⚙ Parámetros'!D17/(1+2^(-'⚙ Parámetros'!C17*(P11-'⚙ Parámetros'!B17))),'⚙ Parámetros'!G17/(1+2^(-'⚙ Parámetros'!F17*(P11-'⚙ Parámetros'!E17))),1)+20/100*MAX('⚙ Parámetros'!D17/(1+2^(-'⚙ Parámetros'!C17*(Q11-'⚙ Parámetros'!B17))),'⚙ Parámetros'!G17/(1+2^(-'⚙ Parámetros'!F17*(Q11-'⚙ Parámetros'!E17))),1)),0) -> 5.4102564 | AE11: =IFERROR((30/100*MAX('⚙ Parámetros'!D18/(1+2^(-'⚙ Parámetros'!C18*(R11-'⚙ Parámetros'!B18))),'⚙ Parámetros'!G18/(1+2^(-'⚙ Parámetros'!F18*(R11-'⚙ Parámetros'!E18))),1)*R11+30/100*MAX('⚙ Parámetros'!D18/(1+2^(-'⚙ Parámetros'!C18*(S11-'⚙ Parámetros'!B18))),'⚙ Parámetros'!G18/(1+2^(-'⚙ Parámetros'!F18*(S11-'⚙ Parámetros'!E18))),1)*S11+20/100*MAX('⚙ Parámetros'!D18/(1+2^(-'⚙ Parámetros'!C18*(T11-'⚙ Parámetros'!B18))),'⚙ Parámetros'!G18/(1+2^(-'⚙ Parámetros'!F18*(T11-'⚙ Parámetros'!E18))),1)*T11+20/100*MAX('⚙ Parámetros'!D18/(1+2^(-'⚙ Parámetros'!C18*(U11-'⚙ Parámetros'!B18))),'⚙ Parámetros'!G18/(1+2^(-'⚙ Parámetros'!F18*(U11-'⚙ Parámetros'!E18))),1)*U11)/(30/100*MAX('⚙ Parámetros'!D18/(1+2^(-'⚙ Parámetros'!C18*(R11-'⚙ Parámetros'!B18))),'⚙ Parámetros'!G18/(1+2^(-'⚙ Parámetros'!F18*(R11-'⚙ Parámetros'!E18))),1)+30/100*MAX('⚙ Parámetros'!D18/(1+2^(-'⚙ Parámetros'!C18*(S11-'⚙ Parámetros'!B18))),'⚙ Parámetros'!G18/(1+2^(-'⚙ Parámetros'!F18*(S11-'⚙ Parámetros'!E18))),1)+20/100*MAX('⚙ Parámetros'!D18/(1+2^(-'⚙ Parámetros'!C18*(T11-'⚙ Parámetros'!B18))),'⚙ Parámetros'!G18/(1+2^(-'⚙ Parámetros'!F18*(T11-'⚙ Parámetros'!E18))),1)+20/100*MAX('⚙ Parámetros'!D18/(1+2^(-'⚙ Parámetros'!C18*(U11-'⚙ Parámetros'!B18))),'⚙ Parámetros'!G18/(1+2^(-'⚙ Parámetros'!F18*(U11-'⚙ Parámetros'!E18))),1)),0) -> 8.180106 | AF11: =IFERROR((30/100*MAX('⚙ Parámetros'!D19/(1+2^(-'⚙ Parámetros'!C19*(V11-'⚙ Parámetros'!B19))),'⚙ Parámetros'!G19/(1+2^(-'⚙ Parámetros'!F19*(V11-'⚙ Parámetros'!E19))),1)*V11+35/100*MAX('⚙ Parámetros'!D19/(1+2^(-'⚙ Parámetros'!C19*(W11-'⚙ Parámetros'!B19))),'⚙ Parámetros'!G19/(1+2^(-'⚙ Parámetros'!F19*(W11-'⚙ Parámetros'!E19))),1)*W11+35/100*MAX('⚙ Parámetros'!D19/(1+2^(-'⚙ Parámetros'!C19*(X11-'⚙ Parámetros'!B19))),'⚙ Parámetros'!G19/(1+2^(-'⚙ Parámetros'!F19*(X11-'⚙ Parámetros'!E19))),1)*X11)/(30/100*MAX('⚙ Parámetros'!D19/(1+2^(-'⚙ Parámetros'!C19*(V11-'⚙ Parámetros'!B19))),'⚙ Parámetros'!G19/(1+2^(-'⚙ Parámetros'!F19*(V11-'⚙ Parámetros'!E19))),1)+35/100*MAX('⚙ Parámetros'!D19/(1+2^(-'⚙ Parámetros'!C19*(W11-'⚙ Parámetros'!B19))),'⚙ Parámetros'!G19/(1+2^(-'⚙ Parámetros'!F19*(W11-'⚙ Parámetros'!E19))),1)+35/100*MAX('⚙ Parámetros'!D19/(1+2^(-'⚙ Parámetros'!C19*(X11-'⚙ Parámetros'!B19))),'⚙ Parámetros'!G19/(1+2^(-'⚙ Parámetros'!F19*(X11-'⚙ Parámetros'!E19))),1)),0) -> 6.1538462 | AG11: =IFERROR((35/100*MAX('⚙ Parámetros'!D20/(1+2^(-'⚙ Parámetros'!C20*(Y11-'⚙ Parámetros'!B20))),'⚙ Parámetros'!G20/(1+2^(-'⚙ Parámetros'!F20*(Y11-'⚙ Parámetros'!E20))),1)*Y11+35/100*MAX('⚙ Parámetros'!D20/(1+2^(-'⚙ Parámetros'!C20*(Z11-'⚙ Parámetros'!B20))),'⚙ Parámetros'!G20/(1+2^(-'⚙ Parámetros'!F20*(Z11-'⚙ Parámetros'!E20))),1)*Z11+30/100*MAX('⚙ Parámetros'!D20/(1+2^(-'⚙ Parámetros'!C20*(AA11-'⚙ Parámetros'!B20))),'⚙ Parámetros'!G20/(1+2^(-'⚙ Parámetros'!F20*(AA11-'⚙ Parámetros'!E20))),1)*AA11)/(35/100*MAX('⚙ Parámetros'!D20/(1+2^(-'⚙ Parámetros'!C20*(Y11-'⚙ Parámetros'!B20))),'⚙ Parámetros'!G20/(1+2^(-'⚙ Parámetros'!F20*(Y11-'⚙ Parámetros'!E20))),1)+35/100*MAX('⚙ Parámetros'!D20/(1+2^(-'⚙ Parámetros'!C20*(Z11-'⚙ Parámetros'!B20))),'⚙ Parámetros'!G20/(1+2^(-'⚙ Parámetros'!F20*(Z11-'⚙ Parámetros'!E20))),1)+30/100*MAX('⚙ Parámetros'!D20/(1+2^(-'⚙ Parámetros'!C20*(AA11-'⚙ Parámetros'!B20))),'⚙ Parámetros'!G20/(1+2^(-'⚙ Parámetros'!F20*(AA11-'⚙ Parámetros'!E20))),1)),0) -> 3.7272727 | AH11: =('⚙ Parámetros'!B5/100*AB11+'⚙ Parámetros'!B6/100*AC11+'⚙ Parámetros'!B7/100*AD11+'⚙ Parámetros'!B8/100*AE11+'⚙ Parámetros'!B9/100*AF11+'⚙ Parámetros'!B10/100*AG11) -> 6.2052716 | AI11: =MIN(1+MAX(0,TODAY()-DATE(2025,11,25))/365*'⚙ Parámetros'!B33,'⚙ Parámetros'!B34) -> 1.0817808 | AJ11: =IFERROR(MIN(AH11*AI11,10),0) -> 6.7127438 | AK11: =IF(AB11>='⚙ Parámetros'!B23,"⚑ AUTO-PRIOR.(D1≥8)",IF(AJ11>='⚙ Parámetros'!B23,"PRIORITARIO",IF(AJ11>='⚙ Parámetros'!B24,"ALTA PRIORIDAD",IF(AJ11>='⚙ Parámetros'!B25,"PRIORIDAD MEDIA",IF(AJ11>='⚙ Parámetros'!B26,"BAJA PRIORIDAD","DESCARTAR"))))) -> PRIORIDAD MEDIA | AL11: =IF(AB11>=8,"SÍ ⚑","—") -> — | AM11: 49 | AN11: =IF(AM11="","—",IF(AM11<'⚙ Parámetros'!B29,"🟢 Corto",IF(AM11<'⚙ Parámetros'!B30,"🟡 Medio","🔴 Largo"))) -> 🟡 Medio
